Workbook

Sheet Dashboard
A1: DASHBOARD KEUANGAN
A2: PT BIGATRI INDOFLORA PACIFIC
A3: BLOOMORIST
A5: TOTAL PENJUALAN | B5: TOTAL BEBAN (HPP+OPS) | C5: LABA BERSIH | D5: KAS & BANK SAAT INI
A6: ='Laba Rugi'!C8 -> 55819250 | B6: =('Laba Rugi'!C18+'Laba Rugi'!C33) -> 56909911 | C6: ='Laba Rugi'!C42 -> -632661 | D6: ='Neraca Saldo'!C6+'Neraca Saldo'!C7 -> 15641450
A9: RINGKASAN LAPORAN LABA RUGI
A10: Penjualan Bersih | B10: ='Laba Rugi'!C8 -> 55819250
A11: Harga Pokok Penjualan (HPP) | B11: ='Laba Rugi'!C18 -> 35664500
A12: Laba Kotor | B12: ='Laba Rugi'!C20 -> 20154750
A13: Total Beban Operasional | B13: ='Laba Rugi'!C33 -> 21245411
A14: Laba Bersih | B14: ='Laba Rugi'!C42 -> -632661
A16: POSISI KEUANGAN (NERACA)
A17: Total Aktiva | B17: =Neraca!C23 -> 61237339
A18: Total Kewajiban | B18: =Neraca!C27 -> 0
A19: Total Modal | B19: =Neraca!C33 -> 61237339

Sheet Penyusutan Peralatan
A2: Bulan Desember Tahun 2025 | H2: Bulan Agustus Tahun 2026
A3: Nama Aset | B3: Bulan Beli | C3: Harga Perolehan | D3: Penyusutan / Bulan | E3: Akm. Penyusutan | F3: Nilai Buku (Neto) | H3: Nama Aset | I3: Bulan Beli | J3: Harga Perolehan | K3: Penyusutan / Bulan | L3: Akm. Penyusutan | M3: Nilai Buku (Neto)
A4: HP Operasional | B4: September | C4: 5000000 | D4: =C4/48 -> 104166.67 | E4: =D4*4 -> 416666.67 | F4: =C4-E4 -> 4583333.3 | H4: HP Operasional | I4: 45901 | J4: 5000000 | K4: =J4/48 -> 104166.67 | L4: =K4*8 -> 833333.33 | M4: =J4-L4 -> 4166666.7
A5: Meja Kursih | B5: September | C5: 1000000 | D5: =C5/48 -> 20833.333 | E5: =D5*4 -> 83333.333 | F5: =C5-E5 -> 916666.67 | H5: Meja Kursih | I5: 45901 | J5: 1000000 | K5: =J5/48 -> 20833.333 | L5: =K5*8 -> 166666.67 | M5: =J5-L5 -> 833333.33
A6: Komputer | B6: September | C6: 10000000 | D6: =C6/48 -> 208333.33 | E6: =D6*4 -> 833333.33 | F6: =C6-E6 -> 9166666.7 | H6: Komputer | I6: 45901 | J6: 10000000 | K6: =J6/48 -> 208333.33 | L6: =K6*8 -> 1666666.7 | M6: =J6-L6 -> 8333333.3
A7: Tambahan Komputer | B7: Oktober | C7: 686000 | D7: =C7/48 -> 14291.667 | E7: =D7*3 -> 42875 | F7: =C7-E7 -> 643125 | H7: Tambahan Komputer | I7: 45931 | J7: 686000 | K7: =J7/48 -> 14291.667 | L7: =K7*8 -> 114333.33 | M7: =J7-L7 -> 571666.67
A8: CCTV | B8: Oktober | C8: 209000 | D8: =C8/48 -> 4354.1667 | E8: =D8*3 -> 13062.5 | F8: =C8-E8 -> 195937.5 | H8: CCTV | I8: 45931 | J8: 209000 | K8: =J8/48 -> 4354.1667 | L8: =K8*8 -> 34833.333 | M8: =J8-L8 -> 174166.67
A9: Mesin Bor | B9: November | C9: 268909 | D9: =C9/48 -> 5602.2708 | E9: =D9*2 -> 11204.542 | F9: =C9-E9 -> 257704.46 | H9: Mesin Bor | I9: 45962 | J9: 268909 | K9: =J9/48 -> 5602.2708 | L9: =K9*8 -> 44818.167 | M9: =J9-L9 -> 224090.83
A10: Speaker PC | B10: November | C10: 74263 | D10: =C10/48 -> 1547.1458 | E10: =D10*2 -> 3094.2917 | F10: =C10-E10 -> 71168.708 | H10: Speaker PC | I10: 45962 | J10: 74263 | K10: =J10/48 -> 1547.1458 | L10: =K10*8 -> 12377.167 | M10: =J10-L10 -> 61885.833
A11: Gunting Batang | B11: Desember | C11: 61100 | D11: =C11/48 -> 1272.9167 | E11: =D11*1 -> 1272.9167 | F11: =C11-E11 -> 59827.083 | H11: Gunting Batang | I11: 45992 | J11: 61100 | K11: =J11/48 -> 1272.9167 | L11: =K11*8 -> 10183.333 | M11: =J11-L11 -> 50916.667
A12: Tape Dispenser | B12: Desember | C12: 17999 | D12: =C12/48 -> 374.97917 | E12: =D12*1 -> 374.97917 | F12: =C12-E12 -> 17624.021 | H12: Tape Dispenser | I12: 45992 | J12: 17999 | K12: =J12/48 -> 374.97917 | L12: =K12*8 -> 2999.8333 | M12: =J12-L12 -> 14999.167
A13: Tropid | B13: Desember | C13: 151205 | D13: =C13/48 -> 3150.1042 | E13: =D13*1 -> 3150.1042 | F13: =C13-E13 -> 148054.9 | H13: Tropid | I13: 45992 | J13: 151205 | K13: =J13/48 -> 3150.1042 | L13: =K13*8 -> 25200.833 | M13: =J13-L13 -> 126004.17
A14: Total | C14: =SUM(C4:C13) -> 17468476 | D14: =SUM(D4:D13) -> 363926.58 | E14: =SUM(E4:E13) -> 1408367.7 | F14: =SUM(F4:F13) -> 16060108 | H14: Tambahan Tape Dispenser | I14: 46235 | J14: 9500 | K14: =J14/48 -> 197.91667 | L14: =K14*1 -> 197.91667 | M14: =J14-L14 -> 9302.0833
J15: =sum(J4:J14) -> 17477976 | K15: =sum(K4:K14) -> 364124.5 | L15: =sum(L4:L14) -> 2911610.6 | M15: =sum(M4:M14) -> 14566365
H17: Bulan September Tahun 2026
H18: Nama Aset | I18: Bulan Beli | J18: Harga Perolehan | K18: Penyusutan / Bulan | L18: Akm. Penyusutan | M18: Nilai Buku (Neto)
H19: HP Operasional | I19: 45901 | J19: 5000000 | K19: =J19/48 -> 104166.67 | L19: =K19*9 -> 937500 | M19: =J19-L19 -> 4062500
H20: Meja Kursih | I20: 45901 | J20: 1000000 | K20: =J20/48 -> 20833.333 | L20: =K20*9 -> 187500 | M20: =J20-L20 -> 812500
H21: Komputer | I21: 45901 | J21: 10000000 | K21: =J21/48 -> 208333.33 | L21: =K21*9 -> 1875000 | M21: =J21-L21 -> 8125000
H22: Tambahan Komputer | I22: 45931 | J22: 686000 | K22: =J22/48 -> 14291.667 | L22: =K22*9 -> 128625 | M22: =J22-L22 -> 557375
H23: CCTV | I23: 45931 | J23: 209000 | K23: =J23/48 -> 4354.1667 | L23: =K23*9 -> 39187.5 | M23: =J23-L23 -> 169812.5
H24: Mesin Bor | I24: 45962 | J24: 268909 | K24: =J24/48 -> 5602.2708 | L24: =K24*9 -> 50420.438 | M24: =J24-L24 -> 218488.56
H25: Speaker PC | I25: 45962 | J25: 74263 | K25: =J25/48 -> 1547.1458 | L25: =K25*9 -> 13924.312 | M25: =J25-L25 -> 60338.688
H26: Gunting Batang | I26: 45992 | J26: 61100 | K26: =J26/48 -> 1272.9167 | L26: =K26*9 -> 11456.25 | M26: =J26-L26 -> 49643.75
H27: Tape Dispenser | I27: 45992 | J27: 17999 | K27: =J27/48 -> 374.97917 | L27: =K27*9 -> 3374.8125 | M27: =J27-L27 -> 14624.188
H28: Tropid | I28: 45992 | J28: 151205 | K28: =J28/48 -> 3150.1042 | L28: =K28*9 -> 28350.938 | M28: =J28-L28 -> 122854.06
H29: Tambahan Tape Dispenser | I29: 46235 | J29: 9500 | K29: =J29/48 -> 197.91667 | L29: =K29*9 -> 1781.25 | M29: =J29-L29 -> 7718.75
J30: =SUM(J19:J29) -> 17477976 | K30: =SUM(K19:K29) -> 364124.5 | L30: =SUM(L19:L29) -> 3277120.5 | M30: =SUM(M19:M29) -> 14200856
H33: Bulan Oktober Tahun 2026
H34: Nama Aset | I34: Bulan Beli | J34: Harga Perolehan | K34: Penyusutan / Bulan | L34: Akm. Penyusutan | M34: Nilai Buku (Neto)
H35: HP Operasional | I35: 45901 | J35: 5000000 | K35: =J35/48 -> 104166.67 | L35: =K35*10 -> 1041666.7 | M35: =M19-L35 -> 3020833.3
H36: Meja Kursih | I36: 45901 | J36: 1000000 | K36: =J36/48 -> 20833.333 | L36: =K36*10 -> 208333.33 | M36: =M20-L36 -> 604166.67
H37: Komputer | I37: 45901 | J37: 10000000 | K37: =J37/48 -> 208333.33 | L37: =K37*10 -> 2083333.3 | M37: =M21-L37 -> 6041666.7
H38: Tambahan Komputer | I38: 45931 | J38: 686000 | K38: =J38/48 -> 14291.667 | L38: =K38*10 -> 142916.67 | M38: =M22-L38 -> 414458.33
H39: CCTV | I39: 45931 | J39: 209000 | K39: =J39/48 -> 4354.1667 | L39: =K39*10 -> 43541.667 | M39: =M23-L39 -> 126270.83
H40: Mesin Bor | I40: 45962 | J40: 268909 | K40: =J40/48 -> 5602.2708 | L40: =K40*10 -> 56022.708 | M40: =M24-L40 -> 162465.85
H41: Speaker PC | I41: 45962 | J41: 74263 | K41: =J41/48 -> 1547.1458 | L41: =K41*10 -> 15471.458 | M41: =M25-L41 -> 44867.229
H42: Gunting Batang | I42: 45992 | J42: 61100 | K42: =J42/48 -> 1272.9167 | L42: =K42*10 -> 12729.167 | M42: =M26-L42 -> 36914.583
H43: Tape Dispenser | I43: 45992 | J43: 17999 | K43: =J43/48 -> 374.97917 | L43: =K43*10 -> 3749.7917 | M43: =M27-L43 -> 10874.396
H44: Tropid | I44: 45992 | J44: 151205 | K44: =J44/48 -> 3150.1042 | L44: =K44*10 -> 31501.042 | M44: =M28-L44 -> 91353.021
...

Sheet Daftar Akun
A1: BLOOMORIST
A3: DAFTAR AKUN (CHART OF ACCOUNTS) — Periode Agustus 2026
A5: Kode Akun | B5: Nama Akun | C5: Kategori | D5: Saldo Normal
A6: 1101 | B6: Kas | C6: Aktiva Lancar | D6: Debit
A7: 1102 | B7: Bank | C7: Aktiva Lancar | D7: Debit
A8: 1103 | B8: Piutang Dagang | C8: Aktiva Lancar | D8: Debit
A9: 1104 | B9: Persediaan Bunga | C9: Aktiva Lancar | D9: Debit
A10: 1105 | B10: Peralatan | C10: Aktiva Tetap | D10: Debit
A11: 1106 | B11: Akumulasi Penyusutan Peralatan | C11: Aktiva Tetap (Kontra) | D11: Kredit
A12: 1107 | B12: Piutang Ongkir | C12: Aktiva Lancar | D12: Debit
A13: 1108 | B13: Perlengkapan | C13: Aktiva Lancar | D13: Debit
A14: 1109 | B14: Piutang Investasi | C14: Aktiva Lancar | D14: Debet
A15: 1110 | B15: Uang Muka Pembelian Petani | C15: Aktiva Lancar | D15: Debit
A16: 1111 | B16: Gaji Bayar di Muka | C16: Aktiva Lancar | D16: Debit
... A39: 6110 | B39: Beban Pesangon | C39: Beban Operasional | D39: Debit

Sheet Jurnal Umum
A1: PT BIGATRI INDOFLORA PACIFIC
A2: BLOOMORIST
A3: JURNAL UMUM — Periode Agustus 2026
A5: Tanggal | B5: No. Bukti | C5: Keterangan | D5: Kode Akun | E5: Nama Akun | F5: Debit (Rp) | G5: Kredit (Rp) | I5: Urutan/Akun | J5: Kunci Pencarian (jangan dihapus) | L5: Kode Akun Lawan
A6: 46235 | C6: Modal Awal Bulan Agustus 2026 | D6: 1102 | E6: =IFERROR(VLOOKUP(D6,'Daftar Akun'!A$6:$B$103,2,FALSE),"") -> Bank | F6: 59266000 | I6: =IF(D6="","",COUNTIF($D$6:D6,D6)) -> 1 | J6: =IF(D6="","",D6&"-"&I6) -> 1102-1 | K6: =E7 -> Modal Pemilik | L6: =IFERROR(INDEX($D$6:$D$909,MATCH(1,($A$6:$A$909=A6)*($C$6:$C$909=C6)*($D$6:$D$909<>D6),0)),"") -> 3101
A7: 46235 | C7: Modal Awal Bulan Agustus 2026 | D7: 3101 | E7: =IFERROR(VLOOKUP(D7,'Daftar Akun'!A$6:$B$103,2,FALSE),"") -> Modal Pemilik | G7: 59266000 | I7: =IF(D7="","",COUNTIF($D$6:D7,D7)) -> 1 | J7: =IF(D7="","",D7&"-"&I7) -> 3101-1 | K7: =E6 -> Bank | L7: =IFERROR(INDEX($D$6:$D$909,MATCH(1,($A$6:$A$909=A7)*($C$6:$C$909=C7)*($D$6:$D$909<>D7),0)),"") -> 1102
A8: 46235 | C8: Pinjaman Modal Greenhouse | D8: 1109 | E8: =IFERROR(VLOOKUP(D8,'Daftar Akun'!A$6:$B$103,2,FALSE),"") -> Piutang Investasi | F8: 33060000 | I8: =IF(D8="","",COUNTIF($D$6:D8,D8)) -> 1 | J8: =IF(D8="","",D8&"-"&I8) -> 1109-1 | K8: =E9 -> Bank | L8: =IFERROR(INDEX($D$6:$D$909,MATCH(1,($A$6:$A$909=A8)*($C$6:$C$909=C8)*($D$6:$D$909<>D8),0)),"") -> 1102
A9: 46235 | C9: Pinjaman Modal Greenhouse | D9: 1102 | E9: =IFERROR(VLOOKUP(D9,'Daftar Akun'!A$6:$B$103,2,FALSE),"") -> Bank | G9: 33060000 | I9: =IF(D9="","",COUNTIF($D$6:D9,D9)) -> 2 | J9: =IF(D9="","",D9&"-"&I9) -> 1102-2 | K9: =E8 -> Piutang Investasi | L9: =IFERROR(INDEX($D$6:$D$909,MATCH(1,($A$6:$A$909=A9)*($C$6:$C$909=C9)*($D$6:$D$909<>D9),0)),"") -> 1109
A10: 46235 | C10: Abunemen Petani Aster - Mas Yuli | D10: 1110 | E10: =IFERROR(VLOOKUP(D10,'Daftar Akun'!A$6:$B$103,2,FALSE),"") -> Uang Muka Pembelian Petani | F10: 7000000 | I10: =IF(D10="","",COUNTIF($D$6:D10,D10)) -> 1 | J10: =IF(D10="","",D10&"-"&I10) -> 1110-1 | K10: =E11 -> Bank | L10: =IFERROR(INDEX($D$6:$D$909,MATCH(1,($A$6:$A$909=A10)*($C$6:$C$909=C10)*($D$6:$D$909<>D10),0)),"") -> 1102
A11: 46235 | C11: Abunemen Petani Aster - Mas Yuli | D11: 1102 | E11: =IFERROR(VLOOKUP(D11,'Daftar Akun'!A$6:$B$103,2,FALSE),"") -> Bank | G11: 7000000 | I11: =IF(D11="","",COUNTIF($D$6:D11,D11)) -> 3 | J11: =IF(D11="","",D11&"-"&I11) -> 1102-3 | K11: =E10 -> Uang Muka Pembelian Petani | L11: =IFERROR(INDEX($D$6:$D$909,MATCH(1,($A$6:$A$909=A11)*($C$6:$C$909=C11)*($D$6:$D$909<>D11),0)),"") -> 1110
A12: 46235 | C12: Talangan Ongkir DMK Cargo | D12: 1107 | E12: =IFERROR(VLOOKUP(D12,'Daftar Akun'!A$6:$B$103,2,FALSE),"") -> Piutang Ongkir | F12: 854295 | I12: =IF(D12="","",COUNTIF($D$6:D12,D12)) -> 1 | J12: =IF(D12="","",D12&"-"&I12) -> 1107-1 | K12: =E13 -> Bank | L12: =IFERROR(INDEX($D$6:$D$909,MATCH(1,($A$6:$A$909=A12)*($C$6:$C$909=C12)*($D$6:$D$909<>D12),0)),"") -> 1102
A13: 46235 | C13: Talangan Ongkir DMK Cargo | D13: 1102 | E13: =IFERROR(VLOOKUP(D13,'Daftar Akun'!A$6:$B$103,2,FALSE),"") -> Bank | G13: 854295 | I13: =IF(D13="","",COUNTIF($D$6:D13,D13)) -> 4 | J13: =IF(D13="","",D13&"-"&I13) -> 1102-4 | K13: =E12 -> Piutang Ongkir | L13: =IFERROR(INDEX($D$6:$D$909,MATCH(1,($A$6:$A$909=A13)*($C$6:$C$909=C13)*($D$6:$D$909<>D13),0)),"") -> 1107
A14: 46235 | C14: Pembayaran Bunga Pikok - Bu Nisa | D14: 5101 | E14: =IFERROR(VLOOKUP(D14,'Daftar Akun'!A$6:$B$103,2,FALSE),"") -> Pembelian Bunga | F14: 1050000 | I14: =IF(D14="","",COUNTIF($D$6:D14,D14)) -> 1 | J14: =IF(D14="","",D14&"-"&I14) -> 5101-1 | K14: =E15 -> Bank | L14: =IFERROR(INDEX($D$6:$D$909,MATCH(1,($A$6:$A$909=A14)*($C$6:$C$909=C14)*($D$6:$D$909<>D14),0)),"") -> 1102
A15: 46235 | C15: Pembayaran Bunga Pikok - Bu Nisa | D15: 1102 | E15: =IFERROR(VLOOKUP(D15,'Daftar Akun'!A$6:$B$103,2,FALSE),"") -> Bank | G15: 1050000 | I15: =IF(D15="","",COUNTIF($D$6:D15,D15)) -> 5 | J15: =IF(D15="","",D15&"-"&I15) -> 1102-5 | K15: =E14 -> Pembelian Bunga | L15: =IFERROR(INDEX($D$6:$D$909,MATCH(1,($A$6:$A$909=A15)*($C$6:$C$909=C15)*($D$6:$D$909<>D15),0)),"") -> 5101
A16: 46235 | C16: Pembayaran Bunga Bromo - Nongkojajar | D16: 5101 | E16: =IFERROR(VLOOKUP(D16,'Daftar Akun'!A$6:$B$103,2,FALSE),"") -> Pembelian Bunga | F16: 1428000 | I16: =IF(D16="","",COUNTIF($D$6:D16,D16)) -> 2 | J16: =IF(D16="","",D16&"-"&I16) -> 5101-2 | K16: =E17 -> Bank | L16: =IFERROR(INDEX($D$6:$D$909,MATCH(1,($A$6:$A$909=A16)*($C$6:$C$909=C16)*($D$6:$D$909<>D16),0)),"") -> 1102
A17: 46235 | C17: Pembayaran Bunga Bromo - Nongkojajar | D17: 1102 | E17: =IFERROR(VLOOKUP(D17,'Daftar Akun'!A$6:$B$103,2,FALSE),"") -> Bank | G17: 1428000 | I17: =IF(D17="","",COUNTIF($D$6:D17,D17)) -> 6 | J17: =IF(D17="","",D17&"-"&I17) -> 1102-6 | K17: =E16 -> Pembelian Bunga | L17: =IFERROR(INDEX($D$6:$D$909,MATCH(1,($A$6:$A$909=A17)*($C$6:$C$909=C17)*($D$6:$D$909<>D17),0)),"") -> 5101
A18: 46235 | C18: Pembelian Bunga di Om Toha | D18: 5101 | E18: =IFERROR(VLOOKUP(D18,'Daftar Akun'!A$6:$B$103,2,FALSE),"") -> Pembelian Bunga | F18: 650000 | I18: =IF(D18="","",COUNTIF($D$6:D18,D18)) -> 3 | J18: =IF(D18="","",D18&"-"&I18) -> 5101-3 | K18: =E19 -> Bank | L18: =IFERROR(INDEX($D$6:$D$909,MATCH(1,($A$6:$A$909=A18)*($C$6:$C$909=C18)*($D$6:$D$909<>D18),0)),"") -> 1102
A19: 46235 | C19: Pembelian Bunga di Om Toha | D19: 1102 | E19: =IFERROR(VLOOKUP(D19,'Daftar Akun'!A$6:$B$103,2,FALSE),"") -> Bank | G19: 650000 | I19: =IF(D19="","",COUNTIF($D$6:D19,D19)) -> 7 | J19: =IF(D19="","",D19&"-"&I19) -> 1102-7 | K19: =E18 -> Pembelian Bunga | L19: =IFERROR(INDEX($D$6:$D$909,MATCH(1,($A$6:$A$909=A19)*($C$6:$C$909=C19)*($D$6:$D$909<>D19),0)),"") -> 5101
A20: 46235 | B20: BK-260801-001 | C20: Pembelian Bunga di WKF | D20: 5101 | E20: =IFERROR(VLOOKUP(D20,'Daftar Akun'!A$6:$B$103,2,FALSE),"") -> Pembelian Bunga | F20: 282000 | I20: =IF(D20="","",COUNTIF($D$6:D20,D20)) -> 4 | J20: =IF(D20="","",D20&"-"&I20) -> 5101-4 | K20: =E21 -> Bank | L20: =IFERROR(INDEX($D$6:$D$909,MATCH(1,($A$6:$A$909=A20)*($C$6:$C$909=C20)*($D$6:$D$909<>D20),0)),"") -> 1102
A21: 46235 | B21: BK-260801-001 | C21: Pembelian Bunga di WKF | D21: 1102 | E21: =IFERROR(VLOOKUP(D21,'Daftar Akun'!A$6:$B$103,2,FALSE),"") -> Bank | G21: 282000 | I21: =IF(D21="","",COUNTIF($D$6:D21,D21)) -> 8 | J21: =IF(D21="","",D21&"-"&I21) -> 1102-8 | K21: =E20 -> Pembelian Bunga | L21: =IFERROR(INDEX($D$6:$D$909,MATCH(1,($A$6:$A$909=A21)*($C$6:$C$909=C21)*($D$6:$D$909<>D21),0)),"") -> 5101
A22: 46235 | C22: Pengembalian Dana Talangan Ongkir | D22: 1102 | E22: =IFERROR(VLOOKUP(D22,'Daftar Akun'!A$6:$B$103,2,FALSE),"") -> Bank | F22: 854295 | I22: =IF(D22="","",COUNTIF($D$6:D22,D22)) -> 9 | J22: =IF(D22="","",D22&"-"&I22) -> 1102-9 | K22: =E23 -> Piutang Ongkir | L22: =IFERROR(INDEX($D$6:$D$909,MATCH(1,($A$6:$A$909=A22)*($C$6:$C$909=C22)*($D$6:$D$909<>D22),0)),"") -> 1107
A23: 46235 | C23: Pengembalian Dana Talangan Ongkir | D23: 1107 | E23: =IFERROR(VLOOKUP(D23,'Daftar Akun'!A$6:$B$103,2,FALSE),"") -> Piutang Ongkir | G23: 854295 | I23: =IF(D23="","",COUNTIF($D$6:D23,D23)) -> 2 | J23: =IF(D23="","",D23&"-"&I23) -> 1107-2 | K23: =E22 -> Bank | L23: =IFERROR(INDEX($D$6:$D$909,MATCH(1,($A$6:$A$909=A23)*($C$6:$C$909=C23)*($D$6:$D$909<>D23),0)),"") -> 1102
A24: 46235 | C24: Tarik Tunai untuk kas operasional | D24: 1101 | E24: =IFERROR(VLOOKUP(D24,'Daftar Akun'!A$6:$B$103,2,FALSE),"") -> Kas | F24: 1437000 | I24: =IF(D24="","",COUNTIF($D$6:D24,D24)) -> 1 | J24: =IF(D24="","",D24&"-"&I24) -> 1101-1 | K24: =E25 -> Bank | L24: =IFERROR(INDEX($D$6:$D$909,MATCH(1,($A$6:$A$909=A24)*($C$6:$C$909=C24)*($D$6:$D$909<>D24),0)),"") -> 1102
A25: 46235 | C25: Tarik Tunai untuk kas operasional | D25: 1102 | E25: =IFERROR(VLOOKUP(D25,'Daftar Akun'!A$6:$B$103,2,FALSE),"") -> Bank | G25: 1437000 | I25: =IF(D25="","",COUNTIF($D$6:D25,D25)) -> 10 | J25: =IF(D25="","",D25&"-"&I25) -> 1102-10 | K25: =E24 -> Kas | L25: =IFERROR(INDEX($D$6:$D$909,MATCH(1,($A$6:$A$909=A25)*($C$6:$C$909=C25)*($D$6:$D$909<>D25),0)),"") -> 1101
A26: 46235 | C26: Ongkir Pembelian Bunga - Mas Pradan | D26: 5103 | E26: =IFERROR(VLOOKUP(D26,'Daftar Akun'!A$6:$B$103,2,FALSE),"") -> Beban Angkut Pembelian | F26: 35000 | I26: =IF(D26="","",COUNTIF($D$6:D26,D26)) -> 1 | J26: =IF(D26="","",D26&"-"&I26) -> 5103-1 | K26: =E27 -> Kas | L26: =IFERROR(INDEX($D$6:$D$909,MATCH(1,($A$6:$A$909=A26)*($C$6:$C$909=C26)*($D$6:$D$909<>D26),0)),"") -> 1101
A27: 46235 | C27: Ongkir Pembelian Bunga - Mas Pradan | D27: 1101 | E27: =IFERROR(VLOOKUP(D27,'Daftar Akun'!A$6:$B$103,2,FALSE),"") -> Kas | G27: 35000 | I27: =IF(D27="","",COUNTIF($D$6:D27,D27)) -> 2 | J27: =IF(D27="","",D27&"-"&I27) -> 1101-2 | K27: =E26 -> Beban Angkut Pembelian | L27: =IFERROR(INDEX($D$6:$D$909,MATCH(1,($A$6:$A$909=A27)*($C$6:$C$909=C27)*($D$6:$D$909<>D27),0)),"") -> 5103
A28: 46235 | C28: Pembelian Bunga oleh tim operasional | D28: 5101 | E28: =IFERROR(VLOOKUP(D28,'Daftar Akun'!A$6:$B$103,2,FALSE),"") -> Pembelian Bunga | F28: 183000 | I28: =IF(D28="","",COUNTIF($D$6:D28,D28)) -> 5 | J28: =IF(D28="","",D28&"-"&I28) -> 5101-5 | K28: =E29 -> Kas | L28: =IFERROR(INDEX($D$6:$D$909,MATCH(1,($A$6:$A$909=A28)*($C$6:$C$909=C28)*($D$6:$D$909<>D28),0)),"") -> 1101
A29: 46235 | C29: Pembelian Bunga oleh tim operasional | D29: 1101 | E29: =IFERROR(VLOOKUP(D29,'Daftar Akun'!A$6:$B$103,2,FALSE),"") -> Kas | G29: 183000 | I29: =IF(D29="","",COUNTIF($D$6:D29,D29)) -> 3 | J29: =IF(D29="","",D29&"-"&I29) -> 1101-3 | K29: =E28 -> Pembelian Bunga | L29: =IFERROR(INDEX($D$6:$D$909,MATCH(1,($A$6:$A$909=A29)*($C$6:$C$909=C29)*($D$6:$D$909<>D29),0)),"") -> 5101
A30: 46235 | B30: KK-260801-002 | C30: Pembayaran Zainul Florist | D30: 5101 | E30: =IFERROR(VLOOKUP(D30,'Daftar Akun'!A$6:$B$103,2,FALSE),"") -> Pembelian Bunga | F30: 17000 | I30: =IF(D30="","",COUNTIF($D$6:D30,D30)) -> 6 | J30: =IF(D30="","",D30&"-"&I30) -> 5101-6 | K30: =E31 -> Kas | L30: =IFERROR(INDEX($D$6:$D$909,MATCH(1,($A$6:$A$909=A30)*($C$6:$C$909=C30)*($D$6:$D$909<>D30),0)),"") -> 1101
A31: 46235 | B31: KK-260801-002 | C31: Pembayaran Zainul Florist | D31: 1101 | E31: =IFERROR(VLOOKUP(D31,'Daftar Akun'!A$6:$B$103,2,FALSE),"") -> Kas | G31: 17000 | I31: =IF(D31="","",COUNTIF($D$6:D31,D31)) -> 4 | J31: =IF(D31="","",D31&"-"&I31) -> 1101-4 | K31: =E30 -> Pembelian Bunga | L31: =IFERROR(INDEX($D$6:$D$909,MATCH(1,($A$6:$A$909=A31)*($C$6:$C$909=C31)*($D$6:$D$909<>D31),0)),"") -> 5101
A32: 46235 | C32: Talangan Ongkir Travel - Pesona Travel - Ngawi | D32: 1107 | E32: =IFERROR(VLOOKUP(D32,'Daftar Akun'!A$6:$B$103,2,FALSE),"") -> Piutang Ongkir | F32: 70000 | I32: =IF(D32="","",COUNTIF($D$6:D32,D32)) -> 3 | J32: =IF(D32="","",D32&"-"&I32) -> 1107-3 | K32: =E33 -> Kas | L32: =IFERROR(INDEX($D$6:$D$909,MATCH(1,($A$6:$A$909=A32)*($C$6:$C$909=C32)*($D$6:$D$909<>D32),0)),"") -> 1101
A33: 46235 | C33: Talangan Ongkir Travel - Pesona Travel - Ngawi | D33: 1101 | E33: =IFERROR(VLOOKUP(D33,'Daftar Akun'!A$6:$B$103,2,FALSE),"") -> Kas | G33: 70000 | I33: =IF(D33="","",COUNTIF($D$6:D33,D33)) -> 5 | J33: =IF(D33="","",D33&"-"&I33) -> 1101-5 | K33: =E32 -> Piutang Ongkir | L33: =IFERROR(INDEX($D$6:$D$909,MATCH(1,($A$6:$A$909=A33)*($C$6:$C$909=C33)*($D$6:$D$909<>D33),0)),"") -> 1107
A34: 46235 | C34: Talangan Ongkir DMK Cargo | D34: 1107 | E34: =IFERROR(VLOOKUP(D34,'Daftar Akun'!A$6:$B$103,2,FALSE),"") -> Piutang Ongkir | F34: 1968519 | I34: =IF(D34="","",COUNTIF($D$6:D34,D34)) -> 4 | J34: =IF(D34="","",D34&"-"&I34) -> 1107-4 | K34: =E35 -> Bank | L34: =IFERROR(INDEX($D$6:$D$909,MATCH(1,($A$6:$A$909=A34)*($C$6:$C$909=C34)*($D$6:$D$909<>D34),0)),"") -> 1102
A35: 46235 | C35: Talangan Ongkir DMK Cargo | D35: 1102 | E35: =IFERROR(VLOOKUP(D35,'Daftar Akun'!A$6:$B$103,2,FALSE),"") -> Bank | G35: 1968519 | I35: =IF(D35="","",COUNTIF($D$6:D35,D35)) -> 11 | J35: =IF(D35="","",D35&"-"&I35) -> 1102-11 | K35: =E34 -> Piutang Ongkir | L35: =IFERROR(INDEX($D$6:$D$909,MATCH(1,($A$6:$A$909=A35)*($C$6:$C$909=C35)*($D$6:$D$909<>D35),0)),"") -> 1107
A36: 46235 | C36: Biaya Admin Kartu BCA | D36: 6108 | E36: =IFERROR(VLOOKUP(D36,'Daftar Akun'!A$6:$B$103,2,FALSE),"") -> Beban Lain-Lain | F36: 10000 | I36: =IF(D36="","",COUNTIF($D$6:D36,D36)) -> 1 | J36: =IF(D36="","",D36&"-"&I36) -> 6108-1 | K36: =E37 -> Bank | L36: =IFERROR(INDEX($D$6:$D$909,MATCH(1,($A$6:$A$909=A36)*($C$6:$C$909=C36)*($D$6:$D$909<>D36),0)),"") -> 1102
A37: 46235 | C37: Biaya Admin Kartu BCA | D37: 1102 | E37: =IFERROR(VLOOKUP(D37,'Daftar Akun'!A$6:$B$103,2,FALSE),"") -> Bank | G37: 10000 | I37: =IF(D37="","",COUNTIF($D$6:D37,D37)) -> 12 | J37: =IF(D37="","",D37&"-"&I37) -> 1102-12 | K37: =E36 -> Beban Lain-Lain | L37: =IFERROR(INDEX($D$6:$D$909,MATCH(1,($A$6:$A$909=A37)*($C$6:$C$909=C37)*($D$6:$D$909<>D37),0)),"") -> 6108
A38: 46235 | B38: INV-108265324 | C38: Penjualan Bunga - Terry | D38: 1103 | E38: =IFERROR(VLOOKUP(D38,'Daftar Akun'!A$6:$B$103,2,FALSE),"") -> Piutang Dagang | F38: 201000 | I38: =IF(D38="","",COUNTIF($D$6:D38,D38)) -> 1 | J38: =IF(D38="","",D38&"-"&I38) -> 1103-1 | K38: =E39 -> Penjualan | L38: =IFERROR(INDEX($D$6:$D$909,MATCH(1,($A$6:$A$909=A38)*($C$6:$C$909=C38)*($D$6:$D$909<>D38),0)),"") -> 4101
A39: 46235 | B39: INV-108265324 | C39: Penjualan Bunga - Terry | D39: 4101 | E39: =IFERROR(VLOOKUP(D39,'Daftar Akun'!A$6:$B$103,2,FALSE),"") -> Penjualan | G39: 201000 | I39: =IF(D39="","",COUNTIF($D$6:D39,D39)) -> 1 | J39: =IF(D39="","",D39&"-"&I39) -> 4101-1 | K39: =E38 -> Piutang Dagang | L39: =IFERROR(INDEX($D$6:$D$909,MATCH(1,($A$6:$A$909=A39)*($C$6:$C$909=C39)*($D$6:$D$909<>D39),0)),"") -> 1103
A40: 46235 | B40: INV-108268980 | C40: Penjualan Bunga - Sunny | D40: 1103 | E40: =IFERROR(VLOOKUP(D40,'Daftar Akun'!A$6:$B$103,2,FALSE),"") -> Piutang Dagang | F40: 715000 | I40: =IF(D40="","",COUNTIF($D$6:D40,D40)) -> 2 | J40: =IF(D40="","",D40&"-"&I40) -> 1103-2 | K40: =E41 -> Penjualan | L40: =IFERROR(INDEX($D$6:$D$909,MATCH(1,($A$6:$A$909=A40)*($C$6:$C$909=C40)*($D$6:$D$909<>D40),0)),"") -> 4101
A41: 46235 | B41: INV-108268980 | C41: Penjualan Bunga - Sunny | D41: 4101 | E41: =IFERROR(VLOOKUP(D41,'Daftar Akun'!A$6:$B$103,2,FALSE),"") -> Penjualan | G41: 715000 | I41: =IF(D41="","",COUNTIF($D$6:D41,D41)) -> 2 | J41: =IF(D41="","",D41&"-"&I41) -> 4101-2 | K41: =E40 -> Piutang Dagang | L41: =IFERROR(INDEX($D$6:$D$909,MATCH(1,($A$6:$A$909=A41)*($C$6:$C$909=C41)*($D$6:$D$909<>D41),0)),"") -> 1103
...

Sheet Buku Besar
A1: PT BIGATRI INDOFLORA PACIFIC
A2: BLOOMORIST
A3: BUKU BESAR Periode Agustus 2026
A5: Pilih Kode Akun: | B5: 1102 | C5: Nama Akun: | D5: {=IFERROR(INDEX('Daftar Akun'!$B$6:$B$62,MATCH($B$5,'Daftar Akun'!$A$6:$A$62,0)),"")} -> Bank
A6: Saldo Normal: | B6: {=IFERROR(INDEX('Daftar Akun'!$D$6:$D$62,MATCH($B$5,'Daftar Akun'!$A$6:$A$62,0)),"")} -> Debit | C6: Saldo Akhir: | D6: =IF($B$6="Debit",SUMIFS('Jurnal Umum'!$F$6:$F$909,'Jurnal Umum'!$D$6:$D$909,$B$5)-SUMIFS('Jurnal Umum'!$G$6:$G$909,'Jurnal Umum'!$D$6:$D$909,$B$5),SUMIFS('Jurnal Umum'!$G$6:$G$909,'Jurnal Umum'!$D$6:$D$909,$B$5)-SUMIFS('Jurnal Umum'!$F$6:$F$909,'Jurnal Umum'!$D$6:$D$909,$B$5)) -> 13450950
A8: Tanggal | B8: Keterangan | C8: No. Bukti | D8: Debit (Rp) | E8: Kredit (Rp) | F8: Saldo (Rp) | H8: Baris JU
A9: {=IF($H9="","",INDEX('Jurnal Umum'!$A$6:$A$2564,$H9-5))} -> 46235 | B9: {=IF($H9="","",IFERROR(INDEX('Jurnal Umum'!$C$6:$C$2564, MATCH(1, ('Jurnal Umum'!$A$6:$A$2564=INDEX('Jurnal Umum'!$A$6:$A$2564,$H9-5)) * ('Jurnal Umum'!$C$6:$C$2564=INDEX('Jurnal Umum'!$C$6:$C$2564,$H9-5)) * ('Jurnal Umum'!$D$6:$D$2564<>$B$5) ,0)),""))} -> Modal Awal Bulan Agustus 2026 | C9: {=IF($H9="","",INDEX('Jurnal Umum'!$B$6:$B$2564,$H9-5))} | D9: {=IF($H9="","",IF(INDEX('Jurnal Umum'!$F$6:$F$2564,$H9-5)="",0,INDEX('Jurnal Umum'!$F$6:$F$2564,$H9-5)))} -> 59266000 | E9: {=IF($H9="","",IF(INDEX('Jurnal Umum'!$G$6:$G$2564,$H9-5)="",0,INDEX('Jurnal Umum'!$G$6:$G$2564,$H9-5)))} -> 0 | F9: =IF($H9="","",IF($B$6="Debit",SUM($D$9:D9)-SUM($E$9:E9),SUM($E$9:E9)-SUM($D$9:D9))) -> 59266000 | H9: =IFERROR(MATCH($B$5&"-"&1,'Jurnal Umum'!$J$6:$J$909,0)+5,"") -> 6
A10: {=IF($H10="","",INDEX('Jurnal Umum'!$A$6:$A$2564,$H10-5))} -> 46235 | B10: {=IF($H10="","",IFERROR(INDEX('Jurnal Umum'!$C$6:$C$2564, MATCH(1, ('Jurnal Umum'!$A$6:$A$2564=INDEX('Jurnal Umum'!$A$6:$A$2564,$H10-5)) * ('Jurnal Umum'!$C$6:$C$2564=INDEX('Jurnal Umum'!$C$6:$C$2564,$H10-5)) * ('Jurnal Umum'!$D$6:$D$2564<>$B$5) ,0)),""))} -> Pinjaman Modal Greenhouse | C10: {=IF($H10="","",INDEX('Jurnal Umum'!$B$6:$B$2564,$H10-5))} | D10: {=IF($H10="","",IF(INDEX('Jurnal Umum'!$F$6:$F$2564,$H10-5)="",0,INDEX('Jurnal Umum'!$F$6:$F$2564,$H10-5)))} -> 0 | E10: {=IF($H10="","",IF(INDEX('Jurnal Umum'!$G$6:$G$2564,$H10-5)="",0,INDEX('Jurnal Umum'!$G$6:$G$2564,$H10-5)))} -> 33060000 | F10: =IF($H10="","",IF($B$6="Debit",SUM($D$9:D10)-SUM($E$9:E10),SUM($E$9:E10)-SUM($D$9:D10))) -> 26206000 | H10: =IFERROR(MATCH($B$5&"-"&2,'Jurnal Umum'!$J$6:$J$909,0)+5,"") -> 9
A11: {=IF($H11="","",INDEX('Jurnal Umum'!$A$6:$A$2564,$H11-5))} -> 46235 | B11: {=IF($H11="","",IFERROR(INDEX('Jurnal Umum'!$C$6:$C$2564, MATCH(1, ('Jurnal Umum'!$A$6:$A$2564=INDEX('Jurnal Umum'!$A$6:$A$2564,$H11-5)) * ('Jurnal Umum'!$C$6:$C$2564=INDEX('Jurnal Umum'!$C$6:$C$2564,$H11-5)) * ('Jurnal Umum'!$D$6:$D$2564<>$B$5) ,0)),""))} -> Abunemen Petani Aster - Mas Yuli | C11: {=IF($H11="","",INDEX('Jurnal Umum'!$B$6:$B$2564,$H11-5))} | D11: {=IF($H11="","",IF(INDEX('Jurnal Umum'!$F$6:$F$2564,$H11-5)="",0,INDEX('Jurnal Umum'!$F$6:$F$2564,$H11-5)))} -> 0 | E11: {=IF($H11="","",IF(INDEX('Jurnal Umum'!$G$6:$G$2564,$H11-5)="",0,INDEX('Jurnal Umum'!$G$6:$G$2564,$H11-5)))} -> 7000000 | F11: =IF($H11="","",IF($B$6="Debit",SUM($D$9:D11)-SUM($E$9:E11),SUM($E$9:E11)-SUM($D$9:D11))) -> 19206000 | H11: =IFERROR(MATCH($B$5&"-"&3,'Jurnal Umum'!$J$6:$J$909,0)+5,"") -> 11
A12: {=IF($H12="","",INDEX('Jurnal Umum'!$A$6:$A$2564,$H12-5))} -> 46235 | B12: {=IF($H12="","",IFERROR(INDEX('Jurnal Umum'!$C$6:$C$2564, MATCH(1, ('Jurnal Umum'!$A$6:$A$2564=INDEX('Jurnal Umum'!$A$6:$A$2564,$H12-5)) * ('Jurnal Umum'!$C$6:$C$2564=INDEX('Jurnal Umum'!$C$6:$C$2564,$H12-5)) * ('Jurnal Umum'!$D$6:$D$2564<>$B$5) ,0)),""))} -> Talangan Ongkir DMK Cargo | C12: {=IF($H12="","",INDEX('Jurnal Umum'!$B$6:$B$2564,$H12-5))} | D12: {=IF($H12="","",IF(INDEX('Jurnal Umum'!$F$6:$F$2564,$H12-5)="",0,INDEX('Jurnal Umum'!$F$6:$F$2564,$H12-5)))} -> 0 | E12: {=IF($H12="","",IF(INDEX('Jurnal Umum'!$G$6:$G$2564,$H12-5)="",0,INDEX('Jurnal Umum'!$G$6:$G$2564,$H12-5)))} -> 854295 | F12: =IF($H12="","",IF($B$6="Debit",SUM($D$9:D12)-SUM($E$9:E12),SUM($E$9:E12)-SUM($D$9:D12))) -> 18351705 | H12: =IFERROR(MATCH($B$5&"-"&4,'Jurnal Umum'!$J$6:$J$909,0)+5,"") -> 13
A13: {=IF($H13="","",INDEX('Jurnal Umum'!$A$6:$A$2564,$H13-5))} -> 46235 | B13: {=IF($H13="","",IFERROR(INDEX('Jurnal Umum'!$C$6:$C$2564, MATCH(1, ('Jurnal Umum'!$A$6:$A$2564=INDEX('Jurnal Umum'!$A$6:$A$2564,$H13-5)) * ('Jurnal Umum'!$C$6:$C$2564=INDEX('Jurnal Umum'!$C$6:$C$2564,$H13-5)) * ('Jurnal Umum'!$D$6:$D$2564<>$B$5) ,0)),""))} -> Pembayaran Bunga Pikok - Bu Nisa | C13: {=IF($H13="","",INDEX('Jurnal Umum'!$B$6:$B$2564,$H13-5))} | D13: {=IF($H13="","",IF(INDEX('Jurnal Umum'!$F$6:$F$2564,$H13-5)="",0,INDEX('Jurnal Umum'!$F$6:$F$2564,$H13-5)))} -> 0 | E13: {=IF($H13="","",IF(INDEX('Jurnal Umum'!$G$6:$G$2564,$H13-5)="",0,INDEX('Jurnal Umum'!$G$6:$G$2564,$H13-5)))} -> 1050000 | F13: =IF($H13="","",IF($B$6="Debit",SUM($D$9:D13)-SUM($E$9:E13),SUM($E$9:E13)-SUM($D$9:D13))) -> 17301705 | H13: =IFERROR(MATCH($B$5&"-"&5,'Jurnal Umum'!$J$6:$J$909,0)+5,"") -> 15
A14: {=IF($H14="","",INDEX('Jurnal Umum'!$A$6:$A$2564,$H14-5))} -> 46235 | B14: {=IF($H14="","",IFERROR(INDEX('Jurnal Umum'!$C$6:$C$2564, MATCH(1, ('Jurnal Umum'!$A$6:$A$2564=INDEX('Jurnal Umum'!$A$6:$A$2564,$H14-5)) * ('Jurnal Umum'!$C$6:$C$2564=INDEX('Jurnal Umum'!$C$6:$C$2564,$H14-5)) * ('Jurnal Umum'!$D$6:$D$2564<>$B$5) ,0)),""))} -> Pembayaran Bunga Bromo - Nongkojajar | C14: {=IF($H14="","",INDEX('Jurnal Umum'!$B$6:$B$2564,$H14-5))} | D14: {=IF($H14="","",IF(INDEX('Jurnal Umum'!$F$6:$F$2564,$H14-5)="",0,INDEX('Jurnal Umum'!$F$6:$F$2564,$H14-5)))} -> 0 | E14: {=IF($H14="","",IF(INDEX('Jurnal Umum'!$G$6:$G$2564,$H14-5)="",0,INDEX('Jurnal Umum'!$G$6:$G$2564,$H14-5)))} -> 1428000 | F14: =IF($H14="","",IF($B$6="Debit",SUM($D$9:D14)-SUM($E$9:E14),SUM($E$9:E14)-SUM($D$9:D14))) -> 15873705 | H14: =IFERROR(MATCH($B$5&"-"&6,'Jurnal Umum'!$J$6:$J$909,0)+5,"") -> 17
A15: {=IF($H15="","",INDEX('Jurnal Umum'!$A$6:$A$2564,$H15-5))} -> 46235 | B15: {=IF($H15="","",IFERROR(INDEX('Jurnal Umum'!$C$6:$C$2564, MATCH(1, ('Jurnal Umum'!$A$6:$A$2564=INDEX('Jurnal Umum'!$A$6:$A$2564,$H15-5)) * ('Jurnal Umum'!$C$6:$C$2564=INDEX('Jurnal Umum'!$C$6:$C$2564,$H15-5)) * ('Jurnal Umum'!$D$6:$D$2564<>$B$5) ,0)),""))} -> Pembelian Bunga di Om Toha | C15: {=IF($H15="","",INDEX('Jurnal Umum'!$B$6:$B$2564,$H15-5))} | D15: {=IF($H15="","",IF(INDEX('Jurnal Umum'!$F$6:$F$2564,$H15-5)="",0,INDEX('Jurnal Umum'!$F$6:$F$2564,$H15-5)))} -> 0 | E15: {=IF($H15="","",IF(INDEX('Jurnal Umum'!$G$6:$G$2564,$H15-5)="",0,INDEX('Jurnal Umum'!$G$6:$G$2564,$H15-5)))} -> 650000 | F15: =IF($H15="","",IF($B$6="Debit",SUM($D$9:D15)-SUM($E$9:E15),SUM($E$9:E15)-SUM($D$9:D15))) -> 15223705 | H15: =IFERROR(MATCH($B$5&"-"&7,'Jurnal Umum'!$J$6:$J$909,0)+5,"") -> 19
A16: {=IF($H16="","",INDEX('Jurnal Umum'!$A$6:$A$2564,$H16-5))} -> 46235 | B16: {=IF($H16="","",IFERROR(INDEX('Jurnal Umum'!$C$6:$C$2564, MATCH(1, ('Jurnal Umum'!$A$6:$A$2564=INDEX('Jurnal Umum'!$A$6:$A$2564,$H16-5)) * ('Jurnal Umum'!$C$6:$C$2564=INDEX('Jurnal Umum'!$C$6:$C$2564,$H16-5)) * ('Jurnal Umum'!$D$6:$D$2564<>$B$5) ,0)),""))} -> Pembelian Bunga di WKF | C16: {=IF($H16="","",INDEX('Jurnal Umum'!$B$6:$B$2564,$H16-5))} -> BK-260801-001 | D16: {=IF($H16="","",IF(INDEX('Jurnal Umum'!$F$6:$F$2564,$H16-5)="",0,INDEX('Jurnal Umum'!$F$6:$F$2564,$H16-5)))} -> 0 | E16: {=IF($H16="","",IF(INDEX('Jurnal Umum'!$G$6:$G$2564,$H16-5)="",0,INDEX('Jurnal Umum'!$G$6:$G$2564,$H16-5)))} -> 282000 | F16: =IF($H16="","",IF($B$6="Debit",SUM($D$9:D16)-SUM($E$9:E16),SUM($E$9:E16)-SUM($D$9:D16))) -> 14941705 | H16: =IFERROR(MATCH($B$5&"-"&8,'Jurnal Umum'!$J$6:$J$909,0)+5,"") -> 21
A17: {=IF($H17="","",INDEX('Jurnal Umum'!$A$6:$A$2564,$H17-5))} -> 46235 | B17: {=IF($H17="","",IFERROR(INDEX('Jurnal Umum'!$C$6:$C$2564, MATCH(1, ('Jurnal Umum'!$A$6:$A$2564=INDEX('Jurnal Umum'!$A$6:$A$2564,$H17-5)) * ('Jurnal Umum'!$C$6:$C$2564=INDEX('Jurnal Umum'!$C$6:$C$2564,$H17-5)) * ('Jurnal Umum'!$D$6:$D$2564<>$B$5) ,0)),""))} -> Pengembalian Dana Talangan Ongkir | C17: {=IF($H17="","",INDEX('Jurnal Umum'!$B$6:$B$2564,$H17-5))} | D17: {=IF($H17="","",IF(INDEX('Jurnal Umum'!$F$6:$F$2564,$H17-5)="",0,INDEX('Jurnal Umum'!$F$6:$F$2564,$H17-5)))} -> 854295 | E17: {=IF($H17="","",IF(INDEX('Jurnal Umum'!$G$6:$G$2564,$H17-5)="",0,INDEX('Jurnal Umum'!$G$6:$G$2564,$H17-5)))} -> 0 | F17: =IF($H17="","",IF($B$6="Debit",SUM($D$9:D17)-SUM($E$9:E17),SUM($E$9:E17)-SUM($D$9:D17))) -> 15796000 | H17: =IFERROR(MATCH($B$5&"-"&9,'Jurnal Umum'!$J$6:$J$909,0)+5,"") -> 22
A18: {=IF($H18="","",INDEX('Jurnal Umum'!$A$6:$A$2564,$H18-5))} -> 46235 | B18: {=IF($H18="","",IFERROR(INDEX('Jurnal Umum'!$C$6:$C$2564, MATCH(1, ('Jurnal Umum'!$A$6:$A$2564=INDEX('Jurnal Umum'!$A$6:$A$2564,$H18-5)) * ('Jurnal Umum'!$C$6:$C$2564=INDEX('Jurnal Umum'!$C$6:$C$2564,$H18-5)) * ('Jurnal Umum'!$D$6:$D$2564<>$B$5) ,0)),""))} -> Tarik Tunai untuk kas operasional | C18: {=IF($H18="","",INDEX('Jurnal Umum'!$B$6:$B$2564,$H18-5))} | D18: {=IF($H18="","",IF(INDEX('Jurnal Umum'!$F$6:$F$2564,$H18-5)="",0,INDEX('Jurnal Umum'!$F$6:$F$2564,$H18-5)))} -> 0 | E18: {=IF($H18="","",IF(INDEX('Jurnal Umum'!$G$6:$G$2564,$H18-5)="",0,INDEX('Jurnal Umum'!$G$6:$G$2564,$H18-5)))} -> 1437000 | F18: =IF($H18="","",IF($B$6="Debit",SUM($D$9:D18)-SUM($E$9:E18),SUM($E$9:E18)-SUM($D$9:D18))) -> 14359000 | H18: =IFERROR(MATCH($B$5&"-"&10,'Jurnal Umum'!$J$6:$J$909,0)+5,"") -> 25
A19: {=IF($H19="","",INDEX('Jurnal Umum'!$A$6:$A$2564,$H19-5))} -> 46235 | B19: {=IF($H19="","",IFERROR(INDEX('Jurnal Umum'!$C$6:$C$2564, MATCH(1, ('Jurnal Umum'!$A$6:$A$2564=INDEX('Jurnal Umum'!$A$6:$A$2564,$H19-5)) * ('Jurnal Umum'!$C$6:$C$2564=INDEX('Jurnal Umum'!$C$6:$C$2564,$H19-5)) * ('Jurnal Umum'!$D$6:$D$2564<>$B$5) ,0)),""))} -> Talangan Ongkir DMK Cargo | C19: {=IF($H19="","",INDEX('Jurnal Umum'!$B$6:$B$2564,$H19-5))} | D19: {=IF($H19="","",IF(INDEX('Jurnal Umum'!$F$6:$F$2564,$H19-5)="",0,INDEX('Jurnal Umum'!$F$6:$F$2564,$H19-5)))} -> 0 | E19: {=IF($H19="","",IF(INDEX('Jurnal Umum'!$G$6:$G$2564,$H19-5)="",0,INDEX('Jurnal Umum'!$G$6:$G$2564,$H19-5)))} -> 1968519 | F19: =IF($H19="","",IF($B$6="Debit",SUM($D$9:D19)-SUM($E$9:E19),SUM($E$9:E19)-SUM($D$9:D19))) -> 12390481 | H19: =IFERROR(MATCH($B$5&"-"&11,'Jurnal Umum'!$J$6:$J$909,0)+5,"") -> 35
A20: {=IF($H20="","",INDEX('Jurnal Umum'!$A$6:$A$2564,$H20-5))} -> 46235 | B20: {=IF($H20="","",IFERROR(INDEX('Jurnal Umum'!$C$6:$C$2564, MATCH(1, ('Jurnal Umum'!$A$6:$A$2564=INDEX('Jurnal Umum'!$A$6:$A$2564,$H20-5)) * ('Jurnal Umum'!$C$6:$C$2564=INDEX('Jurnal Umum'!$C$6:$C$2564,$H20-5)) * ('Jurnal Umum'!$D$6:$D$2564<>$B$5) ,0)),""))} -> Biaya Admin Kartu BCA | C20: {=IF($H20="","",INDEX('Jurnal Umum'!$B$6:$B$2564,$H20-5))} | D20: {=IF($H20="","",IF(INDEX('Jurnal Umum'!$F$6:$F$2564,$H20-5)="",0,INDEX('Jurnal Umum'!$F$6:$F$2564,$H20-5)))} -> 0 | E20: {=IF($H20="","",IF(INDEX('Jurnal Umum'!$G$6:$G$2564,$H20-5)="",0,INDEX('Jurnal Umum'!$G$6:$G$2564,$H20-5)))} -> 10000 | F20: =IF($H20="","",IF($B$6="Debit",SUM($D$9:D20)-SUM($E$9:E20),SUM($E$9:E20)-SUM($D$9:D20))) -> 12380481 | H20: =IFERROR(MATCH($B$5&"-"&12,'Jurnal Umum'!$J$6:$J$909,0)+5,"") -> 37
A21: {=IF($H21="","",INDEX('Jurnal Umum'!$A$6:$A$2564,$H21-5))} -> 46235 | B21: {=IF($H21="","",IFERROR(INDEX('Jurnal Umum'!$C$6:$C$2564, MATCH(1, ('Jurnal Umum'!$A$6:$A$2564=INDEX('Jurnal Umum'!$A$6:$A$2564,$H21-5)) * ('Jurnal Umum'!$C$6:$C$2564=INDEX('Jurnal Umum'!$C$6:$C$2564,$H21-5)) * ('Jurnal Umum'!$D$6:$D$2564<>$B$5) ,0)),""))} -> Penjualan Bunga Ke Vendor - Mas Abizar | C21: {=IF($H21="","",INDEX('Jurnal Umum'!$B$6:$B$2564,$H21-5))} -> BM-260801-001 | D21: {=IF($H21="","",IF(INDEX('Jurnal Umum'!$F$6:$F$2564,$H21-5)="",0,INDEX('Jurnal Umum'!$F$6:$F$2564,$H21-5)))} -> 48000 | E21: {=IF($H21="","",IF(INDEX('Jurnal Umum'!$G$6:$G$2564,$H21-5)="",0,INDEX('Jurnal Umum'!$G$6:$G$2564,$H21-5)))} -> 0 | F21: =IF($H21="","",IF($B$6="Debit",SUM($D$9:D21)-SUM($E$9:E21),SUM($E$9:E21)-SUM($D$9:D21))) -> 12428481 | H21: =IFERROR(MATCH($B$5&"-"&13,'Jurnal Umum'!$J$6:$J$909,0)+5,"") -> 44
A22: {=IF($H22="","",INDEX('Jurnal Umum'!$A$6:$A$2564,$H22-5))} -> 46235 | B22: {=IF($H22="","",IFERROR(INDEX('Jurnal Umum'!$C$6:$C$2564, MATCH(1, ('Jurnal Umum'!$A$6:$A$2564=INDEX('Jurnal Umum'!$A$6:$A$2564,$H22-5)) * ('Jurnal Umum'!$C$6:$C$2564=INDEX('Jurnal Umum'!$C$6:$C$2564,$H22-5)) * ('Jurnal Umum'!$D$6:$D$2564<>$B$5) ,0)),""))} -> Penjualan Bunga Ke Vendor - Mak Pon | C22: {=IF($H22="","",INDEX('Jurnal Umum'!$B$6:$B$2564,$H22-5))} -> PV-007 | D22: {=IF($H22="","",IF(INDEX('Jurnal Umum'!$F$6:$F$2564,$H22-5)="",0,INDEX('Jurnal Umum'!$F$6:$F$2564,$H22-5)))} -> 675000 | E22: {=IF($H22="","",IF(INDEX('Jurnal Umum'!$G$6:$G$2564,$H22-5)="",0,INDEX('Jurnal Umum'!$G$6:$G$2564,$H22-5)))} -> 0 | F22: =IF($H22="","",IF($B$6="Debit",SUM($D$9:D22)-SUM($E$9:E22),SUM($E$9:E22)-SUM($D$9:D22))) -> 13103481 | H22: =IFERROR(MATCH($B$5&"-"&14,'Jurnal Umum'!$J$6:$J$909,0)+5,"") -> 46
A23: {=IF($H23="","",INDEX('Jurnal Umum'!$A$6:$A$2564,$H23-5))} -> 46237 | B23: {=IF($H23="","",IFERROR(INDEX('Jurnal Umum'!$C$6:$C$2564, MATCH(1, ('Jurnal Umum'!$A$6:$A$2564=INDEX('Jurnal Umum'!$A$6:$A$2564,$H23-5)) * ('Jurnal Umum'!$C$6:$C$2564=INDEX('Jurnal Umum'!$C$6:$C$2564,$H23-5)) * ('Jurnal Umum'!$D$6:$D$2564<>$B$5) ,0)),""))} -> Pengembalian Dana Talangan Ongkir | C23: {=IF($H23="","",INDEX('Jurnal Umum'!$B$6:$B$2564,$H23-5))} | D23: {=IF($H23="","",IF(INDEX('Jurnal Umum'!$F$6:$F$2564,$H23-5)="",0,INDEX('Jurnal Umum'!$F$6:$F$2564,$H23-5)))} -> 2038519 | E23: {=IF($H23="","",IF(INDEX('Jurnal Umum'!$G$6:$G$2564,$H23-5)="",0,INDEX('Jurnal Umum'!$G$6:$G$2564,$H23-5)))} -> 0 | F23: =IF($H23="","",IF($B$6="Debit",SUM($D$9:D23)-SUM($E$9:E23),SUM($E$9:E23)-SUM($D$9:D23))) -> 15142000 | H23: =IFERROR(MATCH($B$5&"-"&15,'Jurnal Umum'!$J$6:$J$909,0)+5,"") -> 48
A24: {=IF($H24="","",INDEX('Jurnal Umum'!$A$6:$A$2564,$H24-5))} -> 46237 | B24: {=IF($H24="","",IFERROR(INDEX('Jurnal Umum'!$C$6:$C$2564, MATCH(1, ('Jurnal Umum'!$A$6:$A$2564=INDEX('Jurnal Umum'!$A$6:$A$2564,$H24-5)) * ('Jurnal Umum'!$C$6:$C$2564=INDEX('Jurnal Umum'!$C$6:$C$2564,$H24-5)) * ('Jurnal Umum'!$D$6:$D$2564<>$B$5) ,0)),""))} -> Pembayaran Penjualan Tanggal 1 | C24: {=IF($H24="","",INDEX('Jurnal Umum'!$B$6:$B$2564,$H24-5))} | D24: {=IF($H24="","",IF(INDEX('Jurnal Umum'!$F$6:$F$2564,$H24-5)="",0,INDEX('Jurnal Umum'!$F$6:$F$2564,$H24-5)))} -> 2301250 | E24: {=IF($H24="","",IF(INDEX('Jurnal Umum'!$G$6:$G$2564,$H24-5)="",0,INDEX('Jurnal Umum'!$G$6:$G$2564,$H24-5)))} -> 0 | F24: =IF($H24="","",IF($B$6="Debit",SUM($D$9:D24)-SUM($E$9:E24),SUM($E$9:E24)-SUM($D$9:D24))) -> 17443250 | H24: =IFERROR(MATCH($B$5&"-"&16,'Jurnal Umum'!$J$6:$J$909,0)+5,"") -> 50
A25: {=IF($H25="","",INDEX('Jurnal Umum'!$A$6:$A$2564,$H25-5))} -> 46237 | B25: {=IF($H25="","",IFERROR(INDEX('Jurnal Umum'!$C$6:$C$2564, MATCH(1, ('Jurnal Umum'!$A$6:$A$2564=INDEX('Jurnal Umum'!$A$6:$A$2564,$H25-5)) * ('Jurnal Umum'!$C$6:$C$2564=INDEX('Jurnal Umum'!$C$6:$C$2564,$H25-5)) * ('Jurnal Umum'!$D$6:$D$2564<>$B$5) ,0)),""))} -> Pembayaran Bunga WKF | C25: {=IF($H25="","",INDEX('Jurnal Umum'!$B$6:$B$2564,$H25-5))} -> BK-260803-001 | D25: {=IF($H25="","",IF(INDEX('Jurnal Umum'!$F$6:$F$2564,$H25-5)="",0,INDEX('Jurnal Umum'!$F$6:$F$2564,$H25-5)))} -> 0 | E25: {=IF($H25="","",IF(INDEX('Jurnal Umum'!$G$6:$G$2564,$H25-5)="",0,INDEX('Jurnal Umum'!$G$6:$G$2564,$H25-5)))} -> 180000 | F25: =IF($H25="","",IF($B$6="Debit",SUM($D$9:D25)-SUM($E$9:E25),SUM($E$9:E25)-SUM($D$9:D25))) -> 17263250 | H25: =IFERROR(MATCH($B$5&"-"&17,'Jurnal Umum'!$J$6:$J$909,0)+5,"") -> 53
A26: {=IF($H26="","",INDEX('Jurnal Umum'!$A$6:$A$2564,$H26-5))} -> 46237 | B26: {=IF($H26="","",IFERROR(INDEX('Jurnal Umum'!$C$6:$C$2564, MATCH(1, ('Jurnal Umum'!$A$6:$A$2564=INDEX('Jurnal Umum'!$A$6:$A$2564,$H26-5)) * ('Jurnal Umum'!$C$6:$C$2564=INDEX('Jurnal Umum'!$C$6:$C$2564,$H26-5)) * ('Jurnal Umum'!$D$6:$D$2564<>$B$5) ,0)),""))} -> Pembayaran Bunga WKF | C26: {=IF($H26="","",INDEX('Jurnal Umum'!$B$6:$B$2564,$H26-5))} -> BK-260803-002 | D26: {=IF($H26="","",IF(INDEX('Jurnal Umum'!$F$6:$F$2564,$H26-5)="",0,INDEX('Jurnal Umum'!$F$6:$F$2564,$H26-5)))} -> 0 | E26: {=IF($H26="","",IF(INDEX('Jurnal Umum'!$G$6:$G$2564,$H26-5)="",0,INDEX('Jurnal Umum'!$G$6:$G$2564,$H26-5)))} -> 50000 | F26: =IF($H26="","",IF($B$6="Debit",SUM($D$9:D26)-SUM($E$9:E26),SUM($E$9:E26)-SUM($D$9:D26))) -> 17213250 | H26: =IFERROR(MATCH($B$5&"-"&18,'Jurnal Umum'!$J$6:$J$909,0)+5,"") -> 55
A27: {=IF($H27="","",INDEX('Jurnal Umum'!$A$6:$A$2564,$H27-5))} -> 46237 | B27: {=IF($H27="","",IFERROR(INDEX('Jurnal Umum'!$C$6:$C$2564, MATCH(1, ('Jurnal Umum'!$A$6:$A$2564=INDEX('Jurnal Umum'!$A$6:$A$2564,$H27-5)) * ('Jurnal Umum'!$C$6:$C$2564=INDEX('Jurnal Umum'!$C$6:$C$2564,$H27-5)) * ('Jurnal Umum'!$D$6:$D$2564<>$B$5) ,0)),""))} -> Pembayaran Bunga di Grace Rose | C27: {=IF($H27="","",INDEX('Jurnal Umum'!$B$6:$B$2564,$H27-5))} | D27: {=IF($H27="","",IF(INDEX('Jurnal Umum'!$F$6:$F$2564,$H27-5)="",0,INDEX('Jurnal Umum'!$F$6:$F$2564,$H27-5)))} -> 0 | E27: {=IF($H27="","",IF(INDEX('Jurnal Umum'!$G$6:$G$2564,$H27-5)="",0,INDEX('Jurnal Umum'!$G$6:$G$2564,$H27-5)))} -> 418000 | F27: =IF($H27="","",IF($B$6="Debit",SUM($D$9:D27)-SUM($E$9:E27),SUM($E$9:E27)-SUM($D$9:D27))) -> 16795250 | H27: =IFERROR(MATCH($B$5&"-"&19,'Jurnal Umum'!$J$6:$J$909,0)+5,"") -> 57
A28: {=IF($H28="","",INDEX('Jurnal Umum'!$A$6:$A$2564,$H28-5))} -> 46237 | B28: {=IF($H28="","",IFERROR(INDEX('Jurnal Umum'!$C$6:$C$2564, MATCH(1, ('Jurnal Umum'!$A$6:$A$2564=INDEX('Jurnal Umum'!$A$6:$A$2564,$H28-5)) * ('Jurnal Umum'!$C$6:$C$2564=INDEX('Jurnal Umum'!$C$6:$C$2564,$H28-5)) * ('Jurnal Umum'!$D$6:$D$2564<>$B$5) ,0)),""))} -> Pembelian Bunga di Vendor - Mak Pon | C28: {=IF($H28="","",INDEX('Jurnal Umum'!$B$6:$B$2564,$H28-5))} | D28: {=IF($H28="","",IF(INDEX('Jurnal Umum'!$F$6:$F$2564,$H28-5)="",0,INDEX('Jurnal Umum'!$F$6:$F$2564,$H28-5)))} -> 0 | E28: {=IF($H28="","",IF(INDEX('Jurnal Umum'!$G$6:$G$2564,$H28-5)="",0,INDEX('Jurnal Umum'!$G$6:$G$2564,$H28-5)))} -> 380000 | F28: =IF($H28="","",IF($B$6="Debit",SUM($D$9:D28)-SUM($E$9:E28),SUM($E$9:E28)-SUM($D$9:D28))) -> 16415250 | H28: =IFERROR(MATCH($B$5&"-"&20,'Jurnal Umum'!$J$6:$J$909,0)+5,"") -> 59
A29: {=IF($H29="","",INDEX('Jurnal Umum'!$A$6:$A$2564,$H29-5))} -> 46237 | B29: {=IF($H29="","",IFERROR(INDEX('Jurnal Umum'!$C$6:$C$2564, MATCH(1, ('Jurnal Umum'!$A$6:$A$2564=INDEX('Jurnal Umum'!$A$6:$A$2564,$H29-5)) * ('Jurnal Umum'!$C$6:$C$2564=INDEX('Jurnal Umum'!$C$6:$C$2564,$H29-5)) * ('Jurnal Umum'!$D$6:$D$2564<>$B$5) ,0)),""))} -> Pembelian Bunga di Vendor - Pak Sumadi | C29: {=IF($H29="","",INDEX('Jurnal Umum'!$B$6:$B$2564,$H29-5))} | D29: {=IF($H29="","",IF(INDEX('Jurnal Umum'!$F$6:$F$2564,$H29-5)="",0,INDEX('Jurnal Umum'!$F$6:$F$2564,$H29-5)))} -> 0 | E29: {=IF($H29="","",IF(INDEX('Jurnal Umum'!$G$6:$G$2564,$H29-5)="",0,INDEX('Jurnal Umum'!$G$6:$G$2564,$H29-5)))} -> 240000 | F29: =IF($H29="","",IF($B$6="Debit",SUM($D$9:D29)-SUM($E$9:E29),SUM($E$9:E29)-SUM($D$9:D29))) -> 16175250 | H29: =IFERROR(MATCH($B$5&"-"&21,'Jurnal Umum'!$J$6:$J$909,0)+5,"") -> 61
A30: {=IF($H30="","",INDEX('Jurnal Umum'!$A$6:$A$2564,$H30-5))} -> 46237 | B30: {=IF($H30="","",IFERROR(INDEX('Jurnal Umum'!$C$6:$C$2564, MATCH(1, ('Jurnal Umum'!$A$6:$A$2564=INDEX('Jurnal Umum'!$A$6:$A$2564,$H30-5)) * ('Jurnal Umum'!$C$6:$C$2564=INDEX('Jurnal Umum'!$C$6:$C$2564,$H30-5)) * ('Jurnal Umum'!$D$6:$D$2564<>$B$5) ,0)),""))} -> Pembelian Bunga ke Vendor - Mba Yeti | C30: {=IF($H30="","",INDEX('Jurnal Umum'!$B$6:$B$2564,$H30-5))} | D30: {=IF($H30="","",IF(INDEX('Jurnal Umum'!$F$6:$F$2564,$H30-5)="",0,INDEX('Jurnal Umum'!$F$6:$F$2564,$H30-5)))} -> 0 | E30: {=IF($H30="","",IF(INDEX('Jurnal Umum'!$G$6:$G$2564,$H30-5)="",0,INDEX('Jurnal Umum'!$G$6:$G$2564,$H30-5)))} -> 390000 | F30: =IF($H30="","",IF($B$6="Debit",SUM($D$9:D30)-SUM($E$9:E30),SUM($E$9:E30)-SUM($D$9:D30))) -> 15785250 | H30: =IFERROR(MATCH($B$5&"-"&22,'Jurnal Umum'!$J$6:$J$909,0)+5,"") -> 81
A31: {=IF($H31="","",INDEX('Jurnal Umum'!$A$6:$A$2564,$H31-5))} -> 46238 | B31: {=IF($H31="","",IFERROR(INDEX('Jurnal Umum'!$C$6:$C$2564, MATCH(1, ('Jurnal Umum'!$A$6:$A$2564=INDEX('Jurnal Umum'!$A$6:$A$2564,$H31-5)) * ('Jurnal Umum'!$C$6:$C$2564=INDEX('Jurnal Umum'!$C$6:$C$2564,$H31-5)) * ('Jurnal Umum'!$D$6:$D$2564<>$B$5) ,0)),""))} -> Pembelian Bunga ke Omniflora | C31: {=IF($H31="","",INDEX('Jurnal Umum'!$B$6:$B$2564,$H31-5))} -> BK-260804-001 | D31: {=IF($H31="","",IF(INDEX('Jurnal Umum'!$F$6:$F$2564,$H31-5)="",0,INDEX('Jurnal Umum'!$F$6:$F$2564,$H31-5)))} -> 0 | E31: {=IF($H31="","",IF(INDEX('Jurnal Umum'!$G$6:$G$2564,$H31-5)="",0,INDEX('Jurnal Umum'!$G$6:$G$2564,$H31-5)))} -> 930000 | F31: =IF($H31="","",IF($B$6="Debit",SUM($D$9:D31)-SUM($E$9:E31),SUM($E$9:E31)-SUM($D$9:D31))) -> 14855250 | H31: =IFERROR(MATCH($B$5&"-"&23,'Jurnal Umum'!$J$6:$J$909,0)+5,"") -> 83
A32: {=IF($H32="","",INDEX('Jurnal Umum'!$A$6:$A$2564,$H32-5))} -> 46238 | B32: {=IF($H32="","",IFERROR(INDEX('Jurnal Umum'!$C$6:$C$2564, MATCH(1, ('Jurnal Umum'!$A$6:$A$2564=INDEX('Jurnal Umum'!$A$6:$A$2564,$H32-5)) * ('Jurnal Umum'!$C$6:$C$2564=INDEX('Jurnal Umum'!$C$6:$C$2564,$H32-5)) * ('Jurnal Umum'!$D$6:$D$2564<>$B$5) ,0)),""))} -> Pembayaran Ongkir Pembelian Bunga - Daytrans | C32: {=IF($H32="","",INDEX('Jurnal Umum'!$B$6:$B$2564,$H32-5))} | D32: {=IF($H32="","",IF(INDEX('Jurnal Umum'!$F$6:$F$2564,$H32-5)="",0,INDEX('Jurnal Umum'!$F$6:$F$2564,$H32-5)))} -> 0 | E32: {=IF($H32="","",IF(INDEX('Jurnal Umum'!$G$6:$G$2564,$H32-5)="",0,INDEX('Jurnal Umum'!$G$6:$G$2564,$H32-5)))} -> 87500 | F32: =IF($H32="","",IF($B$6="Debit",SUM($D$9:D32)-SUM($E$9:E32),SUM($E$9:E32)-SUM($D$9:D32))) -> 14767750 | H32: =IFERROR(MATCH($B$5&"-"&24,'Jurnal Umum'!$J$6:$J$909,0)+5,"") -> 85
A33: {=IF($H33="","",INDEX('Jurnal Umum'!$A$6:$A$2564,$H33-5))} -> 46238 | B33: {=IF($H33="","",IFERROR(INDEX('Jurnal Umum'!$C$6:$C$2564, MATCH(1, ('Jurnal Umum'!$A$6:$A$2564=INDEX('Jurnal Umum'!$A$6:$A$2564,$H33-5)) * ('Jurnal Umum'!$C$6:$C$2564=INDEX('Jurnal Umum'!$C$6:$C$2564,$H33-5)) * ('Jurnal Umum'!$D$6:$D$2564<>$B$5) ,0)),""))} -> Pembelian Paket Data - Mas Refan | C33: {=IF($H33="","",INDEX('Jurnal Umum'!$B$6:$B$2564,$H33-5))} | D33: {=IF($H33="","",IF(INDEX('Jurnal Umum'!$F$6:$F$2564,$H33-5)="",0,INDEX('Jurnal Umum'!$F$6:$F$2564,$H33-5)))} -> 0 | E33: {=IF($H33="","",IF(INDEX('Jurnal Umum'!$G$6:$G$2564,$H33-5)="",0,INDEX('Jurnal Umum'!$G$6:$G$2564,$H33-5)))} -> 2800 | F33: =IF($H33="","",IF($B$6="Debit",SUM($D$9:D33)-SUM($E$9:E33),SUM($E$9:E33)-SUM($D$9:D33))) -> 14764950 | H33: =IFERROR(MATCH($B$5&"-"&25,'Jurnal Umum'!$J$6:$J$909,0)+5,"") -> 93
A34: {=IF($H34="","",INDEX('Jurnal Umum'!$A$6:$A$2564,$H34-5))} -> 46238 | B34: {=IF($H34="","",IFERROR(INDEX('Jurnal Umum'!$C$6:$C$2564, MATCH(1, ('Jurnal Umum'!$A$6:$A$2564=INDEX('Jurnal Umum'!$A$6:$A$2564,$H34-5)) * ('Jurnal Umum'!$C$6:$C$2564=INDEX('Jurnal Umum'!$C$6:$C$2564,$H34-5)) * ('Jurnal Umum'!$D$6:$D$2564<>$B$5) ,0)),""))} -> Talangan Pembayaran Ongkir DMK Cargo | C34: {=IF($H34="","",INDEX('Jurnal Umum'!$B$6:$B$2564,$H34-5))} | D34: {=IF($H34="","",IF(INDEX('Jurnal Umum'!$F$6:$F$2564,$H34-5)="",0,INDEX('Jurnal Umum'!$F$6:$F$2564,$H34-5)))} -> 0 | E34: {=IF($H34="","",IF(INDEX('Jurnal Umum'!$G$6:$G$2564,$H34-5)="",0,INDEX('Jurnal Umum'!$G$6:$G$2564,$H34-5)))} -> 1412159 | F34: =IF($H34="","",IF($B$6="Debit",SUM($D$9:D34)-SUM($E$9:E34),SUM($E$9:E34)-SUM($D$9:D34))) -> 13352791 | H34: =IFERROR(MATCH($B$5&"-"&26,'Jurnal Umum'!$J$6:$J$909,0)+5,"") -> 97
A35: {=IF($H35="","",INDEX('Jurnal Umum'!$A$6:$A$2564,$H35-5))} -> 46238 | B35: {=IF($H35="","",IFERROR(INDEX('Jurnal Umum'!$C$6:$C$2564, MATCH(1, ('Jurnal Umum'!$A$6:$A$2564=INDEX('Jurnal Umum'!$A$6:$A$2564,$H35-5)) * ('Jurnal Umum'!$C$6:$C$2564=INDEX('Jurnal Umum'!$C$6:$C$2564,$H35-5)) * ('Jurnal Umum'!$D$6:$D$2564<>$B$5) ,0)),""))} -> Penjualan Bunga Tanggal 3 | C35: {=IF($H35="","",INDEX('Jurnal Umum'!$B$6:$B$2564,$H35-5))} | D35: {=IF($H35="","",IF(INDEX('Jurnal Umum'!$F$6:$F$2564,$H35-5)="",0,INDEX('Jurnal Umum'!$F$6:$F$2564,$H35-5)))} -> 1327250 | E35: {=IF($H35="","",IF(INDEX('Jurnal Umum'!$G$6:$G$2564,$H35-5)="",0,INDEX('Jurnal Umum'!$G$6:$G$2564,$H35-5)))} -> 0 | F35: =IF($H35="","",IF($B$6="Debit",SUM($D$9:D35)-SUM($E$9:E35),SUM($E$9:E35)-SUM($D$9:D35))) -> 14680041 | H35: =IFERROR(MATCH($B$5&"-"&27,'Jurnal Umum'!$J$6:$J$909,0)+5,"") -> 98
A36: {=IF($H36="","",INDEX('Jurnal Umum'!$A$6:$A$2564,$H36-5))} -> 46238 | B36: {=IF($H36="","",IFERROR(INDEX('Jurnal Umum'!$C$6:$C$2564, MATCH(1, ('Jurnal Umum'!$A$6:$A$2564=INDEX('Jurnal Umum'!$A$6:$A$2564,$H36-5)) * ('Jurnal Umum'!$C$6:$C$2564=INDEX('Jurnal Umum'!$C$6:$C$2564,$H36-5)) * ('Jurnal Umum'!$D$6:$D$2564<>$B$5) ,0)),""))} -> Pengembalian Dana Talangan Ongkir | C36: {=IF($H36="","",INDEX('Jurnal Umum'!$B$6:$B$2564,$H36-5))} | D36: {=IF($H36="","",IF(INDEX('Jurnal Umum'!$F$6:$F$2564,$H36-5)="",0,INDEX('Jurnal Umum'!$F$6:$F$2564,$H36-5)))} -> 1412159 | E36: {=IF($H36="","",IF(INDEX('Jurnal Umum'!$G$6:$G$2564,$H36-5)="",0,INDEX('Jurnal Umum'!$G$6:$G$2564,$H36-5)))} -> 0 | F36: =IF($H36="","",IF($B$6="Debit",SUM($D$9:D36)-SUM($E$9:E36),SUM($E$9:E36)-SUM($D$9:D36))) -> 16092200 | H36: =IFERROR(MATCH($B$5&"-"&28,'Jurnal Umum'!$J$6:$J$909,0)+5,"") -> 100
A37: {=IF($H37="","",INDEX('Jurnal Umum'!$A$6:$A$2564,$H37-5))} -> 46238 | B37: {=IF($H37="","",IFERROR(INDEX('Jurnal Umum'!$C$6:$C$2564, MATCH(1, ('Jurnal Umum'!$A$6:$A$2564=INDEX('Jurnal Umum'!$A$6:$A$2564,$H37-5)) * ('Jurnal Umum'!$C$6:$C$2564=INDEX('Jurnal Umum'!$C$6:$C$2564,$H37-5)) * ('Jurnal Umum'!$D$6:$D$2564<>$B$5) ,0)),""))} -> Pembelian Bunga Pikok di Mas Dana | C37: {=IF($H37="","",INDEX('Jurnal Umum'!$B$6:$B$2564,$H37-5))} | D37: {=IF($H37="","",IF(INDEX('Jurnal Umum'!$F$6:$F$2564,$H37-5)="",0,INDEX('Jurnal Umum'!$F$6:$F$2564,$H37-5)))} -> 0 | E37: {=IF($H37="","",IF(INDEX('Jurnal Umum'!$G$6:$G$2564,$H37-5)="",0,INDEX('Jurnal Umum'!$G$6:$G$2564,$H37-5)))} -> 300000 | F37: =IF($H37="","",IF($B$6="Debit",SUM($D$9:D37)-SUM($E$9:E37),SUM($E$9:E37)-SUM($D$9:D37))) -> 15792200 | H37: =IFERROR(MATCH($B$5&"-"&29,'Jurnal Umum'!$J$6:$J$909,0)+5,"") -> 109
A38: {=IF($H38="","",INDEX('Jurnal Umum'!$A$6:$A$2564,$H38-5))} -> 46239 | B38: {=IF($H38="","",IFERROR(INDEX('Jurnal Umum'!$C$6:$C$2564, MATCH(1, ('Jurnal Umum'!$A$6:$A$2564=INDEX('Jurnal Umum'!$A$6:$A$2564,$H38-5)) * ('Jurnal Umum'!$C$6:$C$2564=INDEX('Jurnal Umum'!$C$6:$C$2564,$H38-5)) * ('Jurnal Umum'!$D$6:$D$2564<>$B$5) ,0)),""))} -> Talangan Ongkir DMK Cargo tanggal 4 | C38: {=IF($H38="","",INDEX('Jurnal Umum'!$B$6:$B$2564,$H38-5))} | D38: {=IF($H38="","",IF(INDEX('Jurnal Umum'!$F$6:$F$2564,$H38-5)="",0,INDEX('Jurnal Umum'!$F$6:$F$2564,$H38-5)))} -> 0 | E38: {=IF($H38="","",IF(INDEX('Jurnal Umum'!$G$6:$G$2564,$H38-5)="",0,INDEX('Jurnal Umum'!$G$6:$G$2564,$H38-5)))} -> 2211476 | F38: =IF($H38="","",IF($B$6="Debit",SUM($D$9:D38)-SUM($E$9:E38),SUM($E$9:E38)-SUM($D$9:D38))) -> 13580724 | H38: =IFERROR(MATCH($B$5&"-"&30,'Jurnal Umum'!$J$6:$J$909,0)+5,"") -> 113
A39: {=IF($H39="","",INDEX('Jurnal Umum'!$A$6:$A$2564,$H39-5))} -> 46239 | B39: {=IF($H39="","",IFERROR(INDEX('Jurnal Umum'!$C$6:$C$2564, MATCH(1, ('Jurnal Umum'!$A$6:$A$2564=INDEX('Jurnal Umum'!$A$6:$A$2564,$H39-5)) * ('Jurnal Umum'!$C$6:$C$2564=INDEX('Jurnal Umum'!$C$6:$C$2564,$H39-5)) * ('Jurnal Umum'!$D$6:$D$2564<>$B$5) ,0)),""))} -> Penjualan Bunga Tanggal 4 | C39: {=IF($H39="","",INDEX('Jurnal Umum'!$B$6:$B$2564,$H39-5))} | D39: {=IF($H39="","",IF(INDEX('Jurnal Umum'!$F$6:$F$2564,$H39-5)="",0,INDEX('Jurnal Umum'!$F$6:$F$2564,$H39-5)))} -> 4075000 | E39: {=IF($H39="","",IF(INDEX('Jurnal Umum'!$G$6:$G$2564,$H39-5)="",0,INDEX('Jurnal Umum'!$G$6:$G$2564,$H39-5)))} -> 0 | F39: =IF($H39="","",IF($B$6="Debit",SUM($D$9:D39)-SUM($E$9:E39),SUM($E$9:E39)-SUM($D$9:D39))) -> 17655724 | H39: =IFERROR(MATCH($B$5&"-"&31,'Jurnal Umum'!$J$6:$J$909,0)+5,"") -> 114
A40: {=IF($H40="","",INDEX('Jurnal Umum'!$A$6:$A$2564,$H40-5))} -> 46239 | B40: {=IF($H40="","",IFERROR(INDEX('Jurnal Umum'!$C$6:$C$2564, MATCH(1, ('Jurnal Umum'!$A$6:$A$2564=INDEX('Jurnal Umum'!$A$6:$A$2564,$H40-5)) * ('Jurnal Umum'!$C$6:$C$2564=INDEX('Jurnal Umum'!$C$6:$C$2564,$H40-5)) * ('Jurnal Umum'!$D$6:$D$2564<>$B$5) ,0)),""))} -> Pengembalian Dana Talangan Ongkir tanggal 4 | C40: {=IF($H40="","",INDEX('Jurnal Umum'!$B$6:$B$2564,$H40-5))} | D40: {=IF($H40="","",IF(INDEX('Jurnal Umum'!$F$6:$F$2564,$H40-5)="",0,INDEX('Jurnal Umum'!$F$6:$F$2564,$H40-5)))} -> 2211476 | E40: {=IF($H40="","",IF(INDEX('Jurnal Umum'!$G$6:$G$2564,$H40-5)="",0,INDEX('Jurnal Umum'!$G$6:$G$2564,$H40-5)))} -> 0 | F40: =IF($H40="","",IF($B$6="Debit",SUM($D$9:D40)-SUM($E$9:E40),SUM($E$9:E40)-SUM($D$9:D40))) -> 19867200 | H40: =IFERROR(MATCH($B$5&"-"&32,'Jurnal Umum'!$J$6:$J$909,0)+5,"") -> 116
A41: {=IF($H41="","",INDEX('Jurnal Umum'!$A$6:$A$2564,$H41-5))} -> 46239 | B41: {=IF($H41="","",IFERROR(INDEX('Jurnal Umum'!$C$6:$C$2564, MATCH(1, ('Jurnal Umum'!$A$6:$A$2564=INDEX('Jurnal Umum'!$A$6:$A$2564,$H41-5)) * ('Jurnal Umum'!$C$6:$C$2564=INDEX('Jurnal Umum'!$C$6:$C$2564,$H41-5)) * ('Jurnal Umum'!$D$6:$D$2564<>$B$5) ,0)),""))} -> Pembelian Bunga di Pro Florist | C41: {=IF($H41="","",INDEX('Jurnal Umum'!$B$6:$B$2564,$H41-5))} | D41: {=IF($H41="","",IF(INDEX('Jurnal Umum'!$F$6:$F$2564,$H41-5)="",0,INDEX('Jurnal Umum'!$F$6:$F$2564,$H41-5)))} -> 0 | E41: {=IF($H41="","",IF(INDEX('Jurnal Umum'!$G$6:$G$2564,$H41-5)="",0,INDEX('Jurnal Umum'!$G$6:$G$2564,$H41-5)))} -> 20000 | F41: =IF($H41="","",IF($B$6="Debit",SUM($D$9:D41)-SUM($E$9:E41),SUM($E$9:E41)-SUM($D$9:D41))) -> 19847200 | H41: =IFERROR(MATCH($B$5&"-"&33,'Jurnal Umum'!$J$6:$J$909,0)+5,"") -> 125
A42: {=IF($H42="","",INDEX('Jurnal Umum'!$A$6:$A$2564,$H42-5))} -> 46239 | B42: {=IF($H42="","",IFERROR(INDEX('Jurnal Umum'!$C$6:$C$2564, MATCH(1, ('Jurnal Umum'!$A$6:$A$2564=INDEX('Jurnal Umum'!$A$6:$A$2564,$H42-5)) * ('Jurnal Umum'!$C$6:$C$2564=INDEX('Jurnal Umum'!$C$6:$C$2564,$H42-5)) * ('Jurnal Umum'!$D$6:$D$2564<>$B$5) ,0)),""))} -> Pembelian Bunga di Vendor - Om Toha | C42: {=IF($H42="","",INDEX('Jurnal Umum'!$B$6:$B$2564,$H42-5))} | D42: {=IF($H42="","",IF(INDEX('Jurnal Umum'!$F$6:$F$2564,$H42-5)="",0,INDEX('Jurnal Umum'!$F$6:$F$2564,$H42-5)))} -> 0 | E42: {=IF($H42="","",IF(INDEX('Jurnal Umum'!$G$6:$G$2564,$H42-5)="",0,INDEX('Jurnal Umum'!$G$6:$G$2564,$H42-5)))} -> 420000 | F42: =IF($H42="","",IF($B$6="Debit",SUM($D$9:D42)-SUM($E$9:E42),SUM($E$9:E42)-SUM($D$9:D42))) -> 19427200 | H42: =IFERROR(MATCH($B$5&"-"&34,'Jurnal Umum'!$J$6:$J$909,0)+5,"") -> 127
...

Sheet Neraca Saldo
A1: PT BIGATRI INDOFLORAPACIFIC
A2: BLOOMORIST
A3: NERACA SALDO (TRIAL BALANCE) — Periode Agustus 2026
A5: Kode Akun | B5: Nama Akun | C5: Debit (Rp) | D5: Kredit (Rp)
A6: 1101 | B6: Kas | C6: =MAX(0,SUMIFS('Jurnal Umum'!$F$6:$F$909,'Jurnal Umum'!$D$6:$D$909,A6)-SUMIFS('Jurnal Umum'!$G$6:$G$909,'Jurnal Umum'!$D$6:$D$909,A6)) -> 2190500 | D6: =MAX(0,SUMIFS('Jurnal Umum'!$G$6:$G$909,'Jurnal Umum'!$D$6:$D$909,A6)-SUMIFS('Jurnal Umum'!$F$6:$F$909,'Jurnal Umum'!$D$6:$D$909,A6)) -> 0
A7: 1102 | B7: Bank | C7: =MAX(0,SUMIFS('Jurnal Umum'!$F$6:$F$909,'Jurnal Umum'!$D$6:$D$909,A7)-SUMIFS('Jurnal Umum'!$G$6:$G$909,'Jurnal Umum'!$D$6:$D$909,A7)) -> 13450950 | D7: =MAX(0,SUMIFS('Jurnal Umum'!$G$6:$G$909,'Jurnal Umum'!$D$6:$D$909,A7)-SUMIFS('Jurnal Umum'!$F$6:$F$909,'Jurnal Umum'!$D$6:$D$909,A7)) -> 0
A8: 1103 | B8: Piutang Dagang | C8: =MAX(0,SUMIFS('Jurnal Umum'!$F$6:$F$909,'Jurnal Umum'!$D$6:$D$909,A8)-SUMIFS('Jurnal Umum'!$G$6:$G$909,'Jurnal Umum'!$D$6:$D$909,A8)) -> 35000 | D8: =MAX(0,SUMIFS('Jurnal Umum'!$G$6:$G$909,'Jurnal Umum'!$D$6:$D$909,A8)-SUMIFS('Jurnal Umum'!$F$6:$F$909,'Jurnal Umum'!$D$6:$D$909,A8)) -> 0
A9: 1105 | B9: Peralatan | C9: =MAX(0,SUMIFS('Jurnal Umum'!$F$6:$F$909,'Jurnal Umum'!$D$6:$D$909,A9)-SUMIFS('Jurnal Umum'!$G$6:$G$909,'Jurnal Umum'!$D$6:$D$909,A9)) -> 9500 | D9: =MAX(0,SUMIFS('Jurnal Umum'!$G$6:$G$909,'Jurnal Umum'!$D$6:$D$909,A9)-SUMIFS('Jurnal Umum'!$F$6:$F$909,'Jurnal Umum'!$D$6:$D$909,A9)) -> 0
A10: 1106 | B10: Akumulasi Penyusutan Peralatan | C10: =MAX(0,SUMIFS('Jurnal Umum'!$F$6:$F$909,'Jurnal Umum'!$D$6:$D$909,A10)-SUMIFS('Jurnal Umum'!$G$6:$G$909,'Jurnal Umum'!$D$6:$D$909,A10)) -> 0 | D10: =MAX(0,SUMIFS('Jurnal Umum'!$G$6:$G$909,'Jurnal Umum'!$D$6:$D$909,A10)-SUMIFS('Jurnal Umum'!$F$6:$F$909,'Jurnal Umum'!$D$6:$D$909,A10)) -> 2911611
A11: 1107 | B11: Piutang Ongkir | C11: =MAX(0,SUMIFS('Jurnal Umum'!$F$6:$F$909,'Jurnal Umum'!$D$6:$D$909,A11)-SUMIFS('Jurnal Umum'!$G$6:$G$909,'Jurnal Umum'!$D$6:$D$909,A11)) -> 0 | D11: =MAX(0,SUMIFS('Jurnal Umum'!$G$6:$G$909,'Jurnal Umum'!$D$6:$D$909,A11)-SUMIFS('Jurnal Umum'!$F$6:$F$909,'Jurnal Umum'!$D$6:$D$909,A11)) -> 0
A12: 2101 | B12: Utang Dagang | C12: =MAX(0,SUMIFS('Jurnal Umum'!$F$6:$F$909,'Jurnal Umum'!$D$6:$D$909,A12)-SUMIFS('Jurnal Umum'!$G$6:$G$909,'Jurnal Umum'!$D$6:$D$909,A12)) -> 0 | D12: =MAX(0,SUMIFS('Jurnal Umum'!$G$6:$G$909,'Jurnal Umum'!$D$6:$D$909,A12)-SUMIFS('Jurnal Umum'!$F$6:$F$909,'Jurnal Umum'!$D$6:$D$909,A12)) -> 0
A13: 3101 | B13: Modal Pemilik | C13: =MAX(0,SUMIFS('Jurnal Umum'!$F$6:$F$909,'Jurnal Umum'!$D$6:$D$909,A13)-SUMIFS('Jurnal Umum'!$G$6:$G$909,'Jurnal Umum'!$D$6:$D$909,A13)) -> 0 | D13: =MAX(0,SUMIFS('Jurnal Umum'!$G$6:$G$909,'Jurnal Umum'!$D$6:$D$909,A13)-SUMIFS('Jurnal Umum'!$F$6:$F$909,'Jurnal Umum'!$D$6:$D$909,A13)) -> 61870000
A14: 3102 | B14: Prive | C14: =MAX(0,SUMIFS('Jurnal Umum'!$F$6:$F$909,'Jurnal Umum'!$D$6:$D$909,A14)-SUMIFS('Jurnal Umum'!$G$6:$G$909,'Jurnal Umum'!$D$6:$D$909,A14)) -> 0 | D14: =MAX(0,SUMIFS('Jurnal Umum'!$G$6:$G$909,'Jurnal Umum'!$D$6:$D$909,A14)-SUMIFS('Jurnal Umum'!$F$6:$F$909,'Jurnal Umum'!$D$6:$D$909,A14)) -> 0
A15: 4101 | B15: Penjualan | C15: =MAX(0,SUMIFS('Jurnal Umum'!$F$6:$F$909,'Jurnal Umum'!$D$6:$D$909,A15)-SUMIFS('Jurnal Umum'!$G$6:$G$909,'Jurnal Umum'!$D$6:$D$909,A15)) -> 0 | D15: =MAX(0,SUMIFS('Jurnal Umum'!$G$6:$G$909,'Jurnal Umum'!$D$6:$D$909,A15)-SUMIFS('Jurnal Umum'!$F$6:$F$909,'Jurnal Umum'!$D$6:$D$909,A15)) -> 55819250
A16: 5101 | B16: Pembelian Bunga | C16: =MAX(0,SUMIFS('Jurnal Umum'!$F$6:$F$909,'Jurnal Umum'!$D$6:$D$909,A16)-SUMIFS('Jurnal Umum'!$G$6:$G$909,'Jurnal Umum'!$D$6:$D$909,A16)) -> 38700000 | D16: =MAX(0,SUMIFS('Jurnal Umum'!$G$6:$G$909,'Jurnal Umum'!$D$6:$D$909,A16)-SUMIFS('Jurnal Umum'!$F$6:$F$909,'Jurnal Umum'!$D$6:$D$909,A16)) -> 0
A17: 5102 | B17: Retur Pembelian | C17: =MAX(0,SUMIFS('Jurnal Umum'!$F$6:$F$909,'Jurnal Umum'!$D$6:$D$909,A17)-SUMIFS('Jurnal Umum'!$G$6:$G$909,'Jurnal Umum'!$D$6:$D$909,A17)) -> 0 | D17: =MAX(0,SUMIFS('Jurnal Umum'!$G$6:$G$909,'Jurnal Umum'!$D$6:$D$909,A17)-SUMIFS('Jurnal Umum'!$F$6:$F$909,'Jurnal Umum'!$D$6:$D$909,A17)) -> 0
... A25: 4102 | B25: Retur Penjualan | C25: =MAX(0,SUMIFS('Jurnal Umum'!$F$6:$F$909,'Jurnal Umum'!$D$6:$D$909,A25)-SUMIFS('Jurnal Umum'!$G$6:$G$909,'Jurnal Umum'!$D$6:$D$909,A25)) -> 0 | D25: =MAX(0,SUMIFS('Jurnal Umum'!$G$6:$G$909,'Jurnal Umum'!$D$6:$D$909,A25)-SUMIFS('Jurnal Umum'!$F$6:$F$909,'Jurnal Umum'!$D$6:$D$909,A25)) -> 0
A26: 1108 | B26: Perlengkapan | C26: =MAX(0,SUMIFS('Jurnal Umum'!$F$6:$F$909,'Jurnal Umum'!$D$6:$D$909,A26)-SUMIFS('Jurnal Umum'!$G$6:$G$909,'Jurnal Umum'!$D$6:$D$909,A26)) -> 351000 | D26: =MAX(0,SUMIFS('Jurnal Umum'!$G$6:$G$909,'Jurnal Umum'!$D$6:$D$909,A26)-SUMIFS('Jurnal Umum'!$F$6:$F$909,'Jurnal Umum'!$D$6:$D$909,A26)) -> 0
A27: 6107 | B27: Beban Perlengkapan | C27: =MAX(0,SUMIFS('Jurnal Umum'!$F$6:$F$909,'Jurnal Umum'!$D$6:$D$909,A27)-SUMIFS('Jurnal Umum'!$G$6:$G$909,'Jurnal Umum'!$D$6:$D$909,A27)) -> 945000 | D27: =MAX(0,SUMIFS('Jurnal Umum'!$G$6:$G$909,'Jurnal Umum'!$D$6:$D$909,A27)-SUMIFS('Jurnal Umum'!$F$6:$F$909,'Jurnal Umum'!$D$6:$D$909,A27)) -> 0
A28: 6108 | B28: Beban Lain-Lain | C28: =MAX(0,SUMIFS('Jurnal Umum'!$F$6:$F$909,'Jurnal Umum'!$D$6:$D$909,A28)-SUMIFS('Jurnal Umum'!$G$6:$G$909,'Jurnal Umum'!$D$6:$D$909,A28)) -> 2659600 | D28: =MAX(0,SUMIFS('Jurnal Umum'!$G$6:$G$909,'Jurnal Umum'!$D$6:$D$909,A28)-SUMIFS('Jurnal Umum'!$F$6:$F$909,'Jurnal Umum'!$D$6:$D$909,A28)) -> 0
A29: 1109 | B29: Piutang Investasi | C29: =MAX(0,SUMIFS('Jurnal Umum'!$F$6:$F$909,'Jurnal Umum'!$D$6:$D$909,A29)-SUMIFS('Jurnal Umum'!$G$6:$G$909,'Jurnal Umum'!$D$6:$D$909,A29)) -> 33060000 | D29: =MAX(0,SUMIFS('Jurnal Umum'!$G$6:$G$909,'Jurnal Umum'!$D$6:$D$909,A29)-SUMIFS('Jurnal Umum'!$F$6:$F$909,'Jurnal Umum'!$D$6:$D$909,A29)) -> 0
A30: 4103 | B30: Pendapatan Bunga | C30: =MAX(0,SUMIFS('Jurnal Umum'!$F$6:$F$909,'Jurnal Umum'!$D$6:$D$909,A30)-SUMIFS('Jurnal Umum'!$G$6:$G$909,'Jurnal Umum'!$D$6:$D$909,A30)) -> 0 | D30: =MAX(0,SUMIFS('Jurnal Umum'!$G$6:$G$909,'Jurnal Umum'!$D$6:$D$909,A30)-SUMIFS('Jurnal Umum'!$F$6:$F$909,'Jurnal Umum'!$D$6:$D$909,A30)) -> 363000
A31: 1110 | B31: Uang Muka Pembelian Petani | C31: =MAX(0,SUMIFS('Jurnal Umum'!$F$6:$F$909,'Jurnal Umum'!$D$6:$D$909,A31)-SUMIFS('Jurnal Umum'!$G$6:$G$909,'Jurnal Umum'!$D$6:$D$909,A31)) -> 9200000 | D31: =MAX(0,SUMIFS('Jurnal Umum'!$G$6:$G$909,'Jurnal Umum'!$D$6:$D$909,A31)-SUMIFS('Jurnal Umum'!$F$6:$F$909,'Jurnal Umum'!$D$6:$D$909,A31)) -> 0
A32: 4104 | B32: Pendapatan Lain-Lain | C32: =MAX(0,SUMIFS('Jurnal Umum'!$F$6:$F$909,'Jurnal Umum'!$D$6:$D$909,A32)-SUMIFS('Jurnal Umum'!$G$6:$G$909,'Jurnal Umum'!$D$6:$D$909,A32)) -> 0 | D32: =MAX(0,SUMIFS('Jurnal Umum'!$G$6:$G$909,'Jurnal Umum'!$D$6:$D$909,A32)-SUMIFS('Jurnal Umum'!$F$6:$F$909,'Jurnal Umum'!$D$6:$D$909,A32)) -> 95000
A33: 6109 | B33: Beban Akomodasi | C33: =MAX(0,SUMIFS('Jurnal Umum'!$F$6:$F$909,'Jurnal Umum'!$D$6:$D$909,A33)-SUMIFS('Jurnal Umum'!$G$6:$G$909,'Jurnal Umum'!$D$6:$D$909,A33)) -> 0 | D33: =MAX(0,SUMIFS('Jurnal Umum'!$G$6:$G$909,'Jurnal Umum'!$D$6:$D$909,A33)-SUMIFS('Jurnal Umum'!$F$6:$F$909,'Jurnal Umum'!$D$6:$D$909,A33)) -> 0
